Workbook

Sheet Aceros_DIN
A1: BARRAS DE ACERO / BETONSTAHL — B500B según DIN 488
A2: Acero B500B: f_yk = 500 N/mm² · f_yd = f_yk/1,15 = 435 N/mm² · E_s = 200 000 N/mm² · ρ = 7850 kg/m³
A4: 1. Propiedades por barra / Eigenschaften je Stab
A5: Denominación / Bezeichnung | B5: d_s [mm] | C5: A_s [mm²] | D5: A_s [cm²] | E5: Perímetro u_s [mm] | F5: Masa / Masse [kg/m]
A6: ="Ø "&B6 -> Ø 6 | B6: 6 | C6: =PI()*B6^2/4 -> 28.274334 | D6: =C6/100 -> 0.28274334 | E6: =PI()*B6 -> 18.849556 | F6: =0.00785*C6 -> 0.22195352
A7: ="Ø "&B7 -> Ø 8 | B7: 8 | C7: =PI()*B7^2/4 -> 50.265482 | D7: =C7/100 -> 0.50265482 | E7: =PI()*B7 -> 25.132741 | F7: =0.00785*C7 -> 0.39458404
A8: ="Ø "&B8 -> Ø 10 | B8: 10 | C8: =PI()*B8^2/4 -> 78.539816 | D8: =C8/100 -> 0.78539816 | E8: =PI()*B8 -> 31.415927 | F8: =0.00785*C8 -> 0.61653756
A9: ="Ø "&B9 -> Ø 12 | B9: 12 | C9: =PI()*B9^2/4 -> 113.09734 | D9: =C9/100 -> 1.1309734 | E9: =PI()*B9 -> 37.699112 | F9: =0.00785*C9 -> 0.88781408
A10: ="Ø "&B10 -> Ø 14 | B10: 14 | C10: =PI()*B10^2/4 -> 153.93804 | D10: =C10/100 -> 1.5393804 | E10: =PI()*B10 -> 43.982297 | F10: =0.00785*C10 -> 1.2084136
A11: ="Ø "&B11 -> Ø 16 | B11: 16 | C11: =PI()*B11^2/4 -> 201.06193 | D11: =C11/100 -> 2.0106193 | E11: =PI()*B11 -> 50.265482 | F11: =0.00785*C11 -> 1.5783361
A12: ="Ø "&B12 -> Ø 20 | B12: 20 | C12: =PI()*B12^2/4 -> 314.15927 | D12: =C12/100 -> 3.1415927 | E12: =PI()*B12 -> 62.831853 | F12: =0.00785*C12 -> 2.4661502
A13: ="Ø "&B13 -> Ø 25 | B13: 25 | C13: =PI()*B13^2/4 -> 490.87385 | D13: =C13/100 -> 4.9087385 | E13: =PI()*B13 -> 78.539816 | F13: =0.00785*C13 -> 3.8533597
A14: ="Ø "&B14 -> Ø 28 | B14: 28 | C14: =PI()*B14^2/4 -> 615.75216 | D14: =C14/100 -> 6.1575216 | E14: =PI()*B14 -> 87.964594 | F14: =0.00785*C14 -> 4.8336545
A15: ="Ø "&B15 -> Ø 32 | B15: 32 | C15: =PI()*B15^2/4 -> 804.24772 | D15: =C15/100 -> 8.0424772 | E15: =PI()*B15 -> 100.53096 | F15: =0.00785*C15 -> 6.3133446
A16: ="Ø "&B16 -> Ø 40 | B16: 40 | C16: =PI()*B16^2/4 -> 1256.6371 | D16: =C16/100 -> 12.566371 | E16: =PI()*B16 -> 125.66371 | F16: =0.00785*C16 -> 9.8646009
A18: 2. Área total A_s [cm²] para n barras / Gesamtquerschnitt für n Stäbe
A19: Ø \ n barras | B19: 1 | C19: 2 | D19: 3 | E19: 4 | F19: 5 | G19: 6 | H19: 7 | I19: 8 | J19: 9 | K19: 10
A20: =A6 -> Ø 6 | B20: =B$19*PI()*$B6^2/4/100 -> 0.28274334 | C20: =C$19*PI()*$B6^2/4/100 -> 0.56548668 | D20: =D$19*PI()*$B6^2/4/100 -> 0.84823002 | E20: =E$19*PI()*$B6^2/4/100 -> 1.1309734 | F20: =F$19*PI()*$B6^2/4/100 -> 1.4137167 | G20: =G$19*PI()*$B6^2/4/100 -> 1.69646 | H20: =H$19*PI()*$B6^2/4/100 -> 1.9792034 | I20: =I$19*PI()*$B6^2/4/100 -> 2.2619467 | ... K20: =K$19*PI()*$B6^2/4/100 -> 2.8274334
A21: =A7 -> Ø 8 | B21: =B$19*PI()*$B7^2/4/100 -> 0.50265482 | C21: =C$19*PI()*$B7^2/4/100 -> 1.0053096 | D21: =D$19*PI()*$B7^2/4/100 -> 1.5079645 | E21: =E$19*PI()*$B7^2/4/100 -> 2.0106193 | F21: =F$19*PI()*$B7^2/4/100 -> 2.5132741 | G21: =G$19*PI()*$B7^2/4/100 -> 3.0159289 | H21: =H$19*PI()*$B7^2/4/100 -> 3.5185838 | I21: =I$19*PI()*$B7^2/4/100 -> 4.0212386 | ... K21: =K$19*PI()*$B7^2/4/100 -> 5.0265482
A22: =A8 -> Ø 10 | B22: =B$19*PI()*$B8^2/4/100 -> 0.78539816 | C22: =C$19*PI()*$B8^2/4/100 -> 1.5707963 | D22: =D$19*PI()*$B8^2/4/100 -> 2.3561945 | E22: =E$19*PI()*$B8^2/4/100 -> 3.1415927 | F22: =F$19*PI()*$B8^2/4/100 -> 3.9269908 | G22: =G$19*PI()*$B8^2/4/100 -> 4.712389 | H22: =H$19*PI()*$B8^2/4/100 -> 5.4977871 | I22: =I$19*PI()*$B8^2/4/100 -> 6.2831853 | ... K22: =K$19*PI()*$B8^2/4/100 -> 7.8539816
A23: =A9 -> Ø 12 | B23: =B$19*PI()*$B9^2/4/100 -> 1.1309734 | C23: =C$19*PI()*$B9^2/4/100 -> 2.2619467 | D23: =D$19*PI()*$B9^2/4/100 -> 3.3929201 | E23: =E$19*PI()*$B9^2/4/100 -> 4.5238934 | F23: =F$19*PI()*$B9^2/4/100 -> 5.6548668 | G23: =G$19*PI()*$B9^2/4/100 -> 6.7858401 | H23: =H$19*PI()*$B9^2/4/100 -> 7.9168135 | I23: =I$19*PI()*$B9^2/4/100 -> 9.0477868 | ... K23: =K$19*PI()*$B9^2/4/100 -> 11.309734
A24: =A10 -> Ø 14 | B24: =B$19*PI()*$B10^2/4/100 -> 1.5393804 | C24: =C$19*PI()*$B10^2/4/100 -> 3.0787608 | D24: =D$19*PI()*$B10^2/4/100 -> 4.6181412 | E24: =E$19*PI()*$B10^2/4/100 -> 6.1575216 | F24: =F$19*PI()*$B10^2/4/100 -> 7.696902 | G24: =G$19*PI()*$B10^2/4/100 -> 9.2362824 | H24: =H$19*PI()*$B10^2/4/100 -> 10.775663 | I24: =I$19*PI()*$B10^2/4/100 -> 12.315043 | ... K24: =K$19*PI()*$B10^2/4/100 -> 15.393804
A25: =A11 -> Ø 16 | B25: =B$19*PI()*$B11^2/4/100 -> 2.0106193 | C25: =C$19*PI()*$B11^2/4/100 -> 4.0212386 | D25: =D$19*PI()*$B11^2/4/100 -> 6.0318579 | E25: =E$19*PI()*$B11^2/4/100 -> 8.0424772 | F25: =F$19*PI()*$B11^2/4/100 -> 10.053096 | G25: =G$19*PI()*$B11^2/4/100 -> 12.063716 | H25: =H$19*PI()*$B11^2/4/100 -> 14.074335 | I25: =I$19*PI()*$B11^2/4/100 -> 16.084954 | ... K25: =K$19*PI()*$B11^2/4/100 -> 20.106193
A26: =A12 -> Ø 20 | B26: =B$19*PI()*$B12^2/4/100 -> 3.1415927 | C26: =C$19*PI()*$B12^2/4/100 -> 6.2831853 | D26: =D$19*PI()*$B12^2/4/100 -> 9.424778 | E26: =E$19*PI()*$B12^2/4/100 -> 12.566371 | F26: =F$19*PI()*$B12^2/4/100 -> 15.707963 | G26: =G$19*PI()*$B12^2/4/100 -> 18.849556 | H26: =H$19*PI()*$B12^2/4/100 -> 21.991149 | I26: =I$19*PI()*$B12^2/4/100 -> 25.132741 | ... K26: =K$19*PI()*$B12^2/4/100 -> 31.415927
A27: =A13 -> Ø 25 | B27: =B$19*PI()*$B13^2/4/100 -> 4.9087385 | C27: =C$19*PI()*$B13^2/4/100 -> 9.817477 | D27: =D$19*PI()*$B13^2/4/100 -> 14.726216 | E27: =E$19*PI()*$B13^2/4/100 -> 19.634954 | F27: =F$19*PI()*$B13^2/4/100 -> 24.543693 | G27: =G$19*PI()*$B13^2/4/100 -> 29.452431 | H27: =H$19*PI()*$B13^2/4/100 -> 34.36117 | I27: =I$19*PI()*$B13^2/4/100 -> 39.269908 | ... K27: =K$19*PI()*$B13^2/4/100 -> 49.087385
A28: =A14 -> Ø 28 | B28: =B$19*PI()*$B14^2/4/100 -> 6.1575216 | C28: =C$19*PI()*$B14^2/4/100 -> 12.315043 | D28: =D$19*PI()*$B14^2/4/100 -> 18.472565 | E28: =E$19*PI()*$B14^2/4/100 -> 24.630086 | F28: =F$19*PI()*$B14^2/4/100 -> 30.787608 | G28: =G$19*PI()*$B14^2/4/100 -> 36.94513 | H28: =H$19*PI()*$B14^2/4/100 -> 43.102651 | I28: =I$19*PI()*$B14^2/4/100 -> 49.260173 | ... K28: =K$19*PI()*$B14^2/4/100 -> 61.575216
A29: =A15 -> Ø 32 | B29: =B$19*PI()*$B15^2/4/100 -> 8.0424772 | C29: =C$19*PI()*$B15^2/4/100 -> 16.084954 | D29: =D$19*PI()*$B15^2/4/100 -> 24.127432 | E29: =E$19*PI()*$B15^2/4/100 -> 32.169909 | F29: =F$19*PI()*$B15^2/4/100 -> 40.212386 | G29: =G$19*PI()*$B15^2/4/100 -> 48.254863 | H29: =H$19*PI()*$B15^2/4/100 -> 56.29734 | I29: =I$19*PI()*$B15^2/4/100 -> 64.339818 | ... K29: =K$19*PI()*$B15^2/4/100 -> 80.424772
A30: =A16 -> Ø 40 | B30: =B$19*PI()*$B16^2/4/100 -> 12.566371 | C30: =C$19*PI()*$B16^2/4/100 -> 25.132741 | D30: =D$19*PI()*$B16^2/4/100 -> 37.699112 | E30: =E$19*PI()*$B16^2/4/100 -> 50.265482 | F30: =F$19*PI()*$B16^2/4/100 -> 62.831853 | G30: =G$19*PI()*$B16^2/4/100 -> 75.398224 | H30: =H$19*PI()*$B16^2/4/100 -> 87.964594 | I30: =I$19*PI()*$B16^2/4/100 -> 100.53096 | ... K30: =K$19*PI()*$B16^2/4/100 -> 125.66371
A33: 3. Clases de hormigón / Betonfestigkeitsklassen (DIN EN 1992-1-1, Tab. 3.1)
A34: Clase / Klasse | B34: f_ck [N/mm²] | C34: f_ck,cube | D34: f_ctm [N/mm²] | E34: f_ctk;0,05 | F34: E_cm [N/mm²]
A35: C12/15 | B35: 12 | C35: 15 | D35: =0.3*B35^(2/3) -> 1.5724448 | E35: =0.7*D35 -> 1.1007114 | F35: =22000*((B35+8)/10)^0.3 -> 27085.177
A36: C16/20 | B36: 16 | C36: 20 | D36: =0.3*B36^(2/3) -> 1.9048813 | E36: =0.7*D36 -> 1.3334169 | F36: =22000*((B36+8)/10)^0.3 -> 28607.905
A37: C20/25 | B37: 20 | C37: 25 | D37: =0.3*B37^(2/3) -> 2.2104189 | E37: =0.7*D37 -> 1.5472932 | F37: =22000*((B37+8)/10)^0.3 -> 29961.951
A38: C25/30 | B38: 25 | C38: 30 | D38: =0.3*B38^(2/3) -> 2.5649639 | E38: =0.7*D38 -> 1.7954747 | F38: =22000*((B38+8)/10)^0.3 -> 31475.806
A39: C30/37 | B39: 30 | C39: 37 | D39: =0.3*B39^(2/3) -> 2.8964682 | E39: =0.7*D39 -> 2.0275277 | F39: =22000*((B39+8)/10)^0.3 -> 32836.568
A40: C35/45 | B40: 35 | C40: 45 | D40: =0.3*B40^(2/3) -> 3.2099624 | E40: =0.7*D40 -> 2.2469737 | F40: =22000*((B40+8)/10)^0.3 -> 34077.146
A41: C40/50 | B41: 40 | C41: 50 | D41: =0.3*B41^(2/3) -> 3.5088213 | E41: =0.7*D41 -> 2.4561749 | F41: =22000*((B41+8)/10)^0.3 -> 35220.462
A42: C45/55 | B42: 45 | C42: 55 | D42: =0.3*B42^(2/3) -> 3.795447 | E42: =0.7*D42 -> 2.6568129 | F42: =22000*((B42+8)/10)^0.3 -> 36283.188
A43: C50/60 | B43: 50 | C43: 60 | D43: =0.3*B43^(2/3) -> 4.0716264 | E43: =0.7*D43 -> 2.8501385 | F43: =22000*((B43+8)/10)^0.3 -> 37277.869
A45: 4. Acero de refuerzo / Betonstahlsorten (DIN 488)
...

Sheet Balken_DIN
A1: BEMESSUNG EINES STAHLBETONBALKENS — BIEGUNG, QUERKRAFT UND TORSION
A2: DIN EN 1992-1-1:2011 (EC2) + DIN EN 1992-1-1/NA:2013 (Nationaler Anhang Deutschland) · Rechteckquerschnitt · Dimensionsloses μ–ξ–ω-Verfahren und äquivalenter Hohlkasten für Torsion (§6.3) | R2: Contorno X | S2: Contorno Y | T2: Estribo X | U2: Estribo Y | V2: Barras inf X | W2: Barras inf Y | X2: Barras sup X | Y2: Barras sup Y
R3: =0 -> 0 | S3: =0 -> 0 | T3: =C11 -> 35 | U3: =C11 -> 35 | V3: =IF(1<=$C$13,$C$33+(1-1)*($C$9-2*$C$33)/MAX($C$13-1,1),NA()) -> 55 | W3: =IF(1<=$C$13,$C$33,NA()) -> 55 | X3: =$C$33 -> 55 | Y3: =$C$10-$C$33 -> 545
A4: 1. EINGABEDATEN (blaue Zellen = editierbar) | R4: =C9 -> 3420 | S4: =0 -> 0 | T4: =C9-C11 -> 3385 | U4: =C11 -> 35 | V4: =IF(2<=$C$13,$C$33+(2-1)*($C$9-2*$C$33)/MAX($C$13-1,1),NA()) -> 606.66667 | W4: =IF(2<=$C$13,$C$33,NA()) -> 55 | X4: =$C$9-$C$33 -> 3365 | Y4: =$C$10-$C$33 -> 545
A5: Parameter | B5: Symbol | C5: Wert | D5: Einheit | E5: Bezug DIN EN 1992-1-1 / NA | F5: Anmerkung / Formel | R5: =C9 -> 3420 | S5: =C10 -> 600 | T5: =C9-C11 -> 3385 | U5: =C10-C11 -> 565 | V5: =IF(3<=$C$13,$C$33+(3-1)*($C$9-2*$C$33)/MAX($C$13-1,1),NA()) -> 1158.3333 | W5: =IF(3<=$C$13,$C$33,NA()) -> 55
A6: Bemessungswert des Biegemoments | B6: M_Ed | C6: 250 | D6: kNm | E6: 6.1 | F6: Bemessungskombination GZT (EN 1990) | R6: =0 -> 0 | S6: =C10 -> 600 | T6: =C11 -> 35 | U6: =C10-C11 -> 565 | V6: =IF(4<=$C$13,$C$33+(4-1)*($C$9-2*$C$33)/MAX($C$13-1,1),NA()) -> 1710 | W6: =IF(4<=$C$13,$C$33,NA()) -> 55
A7: Bemessungswert der Querkraft | B7: V_Ed | C7: 200 | D7: kN | E7: 6.2.1 | R7: =0 -> 0 | S7: =0 -> 0 | T7: =C11 -> 35 | U7: =C11 -> 35 | V7: =IF(5<=$C$13,$C$33+(5-1)*($C$9-2*$C$33)/MAX($C$13-1,1),NA()) -> 2261.6667 | W7: =IF(5<=$C$13,$C$33,NA()) -> 55
A8: Bemessungswert des Torsionsmoments | B8: T_Ed | C8: 25 | D8: kNm | E8: 6.3.1 | V8: =IF(6<=$C$13,$C$33+(6-1)*($C$9-2*$C$33)/MAX($C$13-1,1),NA()) -> 2813.3333 | W8: =IF(6<=$C$13,$C$33,NA()) -> 55
A9: Querschnittsbreite | B9: b | C9: 3420 | D9: mm | E9: — | V9: =IF(7<=$C$13,$C$33+(7-1)*($C$9-2*$C$33)/MAX($C$13-1,1),NA()) -> 3365 | W9: =IF(7<=$C$13,$C$33,NA()) -> 55
A10: Gesamthöhe des Querschnitts | B10: h | C10: 600 | D10: mm | E10: — | V10: =IF(8<=$C$13,$C$33+(8-1)*($C$9-2*$C$33)/MAX($C$13-1,1),NA()) -> #N/A | W10: =IF(8<=$C$13,$C$33,NA()) -> #N/A
A11: Nennmaß der Betondeckung | B11: c_nom | C11: 35 | D11: mm | E11: 4.4.1 / NA Tab. 4.4DE | V11: =IF(9<=$C$13,$C$33+(9-1)*($C$9-2*$C$33)/MAX($C$13-1,1),NA()) -> #N/A | W11: =IF(9<=$C$13,$C$33,NA()) -> #N/A
A12: Durchmesser Längsstab | B12: Ø_l | C12: 20 | D12: mm | E12: — | V12: =IF(10<=$C$13,$C$33+(10-1)*($C$9-2*$C$33)/MAX($C$13-1,1),NA()) -> #N/A | W12: =IF(10<=$C$13,$C$33,NA()) -> #N/A
A13: Anzahl der Längsstäbe (Zugzone) | B13: n_l | C13: 7 | D13: — | E13: — | V13: =IF(11<=$C$13,$C$33+(11-1)*($C$9-2*$C$33)/MAX($C$13-1,1),NA()) -> #N/A | W13: =IF(11<=$C$13,$C$33,NA()) -> #N/A
A14: Durchmesser des Bügels | B14: Ø_w | C14: 10 | D14: mm | E14: 9.2.2 | V14: =IF(12<=$C$13,$C$33+(12-1)*($C$9-2*$C$33)/MAX($C$13-1,1),NA()) -> #N/A | W14: =IF(12<=$C$13,$C$33,NA()) -> #N/A
A15: Anzahl der Bügelschenkel (Querkraft) | B15: n_w | C15: 2 | D15: — | E15: 9.2.2
A16: Charakteristische Betondruckfestigkeit | B16: f_ck | C16: =_xlfn.XLOOKUP(F16,Aceros_DIN!$A$35:$A$43,Aceros_DIN!$B$35:$B$43) -> 30 | D16: N/mm² | E16: Tab. 3.1 | F16: C30/37
A17: Streckgrenze des Betonstahls | B17: f_yk | C17: =_xlfn.XLOOKUP(F17,Aceros_DIN!$A$47:$A$49,Aceros_DIN!$B$47:$B$49) -> 500 | D17: N/mm² | E17: 3.2.2 (B500) | F17: B500B
A18: Teilsicherheitsbeiwert Beton | B18: γ_c | C18: 1.5 | D18: — | E18: Tab. 2.1DE (NA)
A19: Teilsicherheitsbeiwert Betonstahl | B19: γ_s | C19: 1.15 | D19: — | E19: Tab. 2.1DE (NA)
A20: Beiwert Dauerstandeinfluss | B20: α_cc | C20: 0.85 | D20: — | E20: NA 3.1.6(1)
A21: cot θ gewählt (0 = automatisch nach NA) | B21: cot θ | C21: 0 | D21: — | E21: NA 6.2.3(2), Gl. (6.7aDE)
A22: Abminderungsbeiwert Druckstrebe (Torsion) | B22: ν_T | C22: 0.525 | D22: — | E22: NA 6.3.2(4) | F22: ν für Torsionsdruckstreben nach NA (≤ C50/60)
A24: 2. BAUSTOFFE
A25: Bemessungswert der Betondruckfestigkeit | B25: f_cd | C25: =C20*C16/C18 -> 17 | D25: N/mm² | E25: 3.1.6(1), Gl. (3.15) | F25: f_cd = α_cc·f_ck/γ_c
A26: Mittlere Betonzugfestigkeit | B26: f_ctm | C26: =0.3*C16^(2/3) -> 2.8964682 | D26: N/mm² | E26: Tab. 3.1 | F26: f_ctm = 0,30·f_ck^(2/3) für ≤ C50/60
A27: Bemessungswert der Betonzugfestigkeit | B27: f_ctd | C27: =0.85*0.7*C26/C18 -> 1.1489324 | D27: N/mm² | E27: 3.1.6(2), Gl. (3.16) | F27: f_ctd = α_ct·f_ctk;0,05/γ_c = 0,85·0,7·f_ctm/γ_c
A28: Bemessungswert der Stahlstreckgrenze | B28: f_yd | C28: =C17/C19 -> 434.78261 | D28: N/mm² | E28: 3.2.7(2), Bild 3.8 | F28: f_yd = f_yk/γ_s
A29: Grenzdehnung des Betons | B29: ε_cu2 | C29: 0.0035 | D29: — | E29: Tab. 3.1
A30: Bemessungswert der Fließdehnung des Stahls | B30: ε_yd | C30: =C28/200000 -> 0.002173913 | D30: — | E30: 3.2.7(2) | F30: ε_yd = f_yd/E_s ; E_s = 200 000 N/mm²
A32: 3. QUERSCHNITTSGEOMETRIE UND ÄQUIVALENTER HOHLKASTEN (Torsion)
A33: Randabstand bis zum Schwerpunkt der Bewehrung | B33: d₁ | C33: =C11+C14+C12/2 -> 55 | D33: mm | E33: 4.4.1 | F33: d₁ = c_nom + Ø_w + Ø_l/2
A34: Statische Nutzhöhe | B34: d | C34: =C10-C33 -> 545 | D34: mm | E34: 6.1 | F34: d = h − d₁
A35: Betonquerschnittsfläche | B35: A_c | C35: =C9*C10 -> 2052000 | D35: mm² | E35: — | F35: A_c = b·h
A36: Vorhandene Längszugbewehrung | B36: A_s,vorh | C36: =C13*PI()*C12^2/4 -> 2199.1149 | D36: mm² | E36: — | F36: A_s,vorh = n_l·π·Ø_l²/4
A37: Äußerer Umfang des Querschnitts | B37: u | C37: =2*(C9+C10) -> 8040 | D37: mm | E37: 6.3.2(1) | F37: u = 2·(b+h)
A38: Wirksame Wanddicke | B38: t_ef | C38: =MAX(C35/C37,2*C33) -> 255.22388 | D38: mm | E38: 6.3.2(1) | F38: t_ef = A/u , aber ≥ 2·d₁ (Deckung bis Stabmitte)
A39: Von der Mittellinie umschlossene Fläche | B39: A_k | C39: =(C9-C38)*(C10-C38) -> 1091139.2 | D39: mm² | E39: 6.3.2(1) | F39: A_k = (b−t_ef)·(h−t_ef)
A40: Umfang der Mittellinie | B40: u_k | C40: =2*((C9-C38)+(C10-C38)) -> 7019.1045 | D40: mm | E40: 6.3.2(1) | F40: u_k = 2·((b−t_ef)+(h−t_ef))
A41: Innerer Hebelarm (Querkraft/Torsion) | B41: z | C41: =0.9*C34 -> 490.5 | D41: mm | E41: 6.2.3(1) | F41: z ≈ 0,9·d
A43: 4. BIEGEBEMESSUNG — LÄNGSBEWEHRUNG (μ–ξ–ω-Verfahren)
...

Sheet Balken_2025
A1: BEMESSUNG EINES STAHLBETONBALKENS — BIEGUNG, QUERKRAFT UND TORSION
A2: DIN EN 1992-1-1:2025 (EC2) + DIN EN 1992-1-1/NA1:2025 · Rechteckquerschnitt · μ-ξ-ω-Verfahren und äquivalenter Hohlkasten für Torsion (§8.3) | R2: Contorno X | S2: Contorno Y | T2: Estribo X | U2: Estribo Y | V2: Barras inf X | W2: Barras inf Y | X2: Barras sup X | Y2: Barras sup Y
R3: =0 -> 0 | S3: =0 -> 0 | T3: =C11 -> 35 | U3: =C11 -> 35 | V3: =IF(1<=$C$13,$C$33+(1-1)*($C$9-2*$C$33)/MAX($C$13-1,1),NA()) -> 57 | W3: =IF(1<=$C$13,$C$33,NA()) -> 57 | X3: =$C$33 -> 57 | Y3: =$C$10-$C$33 -> 543
A4: 1. EINGABEDATEN (blaue Zellen = editierbar) | R4: =C9 -> 3420 | S4: =0 -> 0 | T4: =C9-C11 -> 3385 | U4: =C11 -> 35 | V4: =IF(2<=$C$13,$C$33+(2-1)*($C$9-2*$C$33)/MAX($C$13-1,1),NA()) -> 424.33333 | W4: =IF(2<=$C$13,$C$33,NA()) -> 57 | X4: =$C$9-$C$33 -> 3363 | Y4: =$C$10-$C$33 -> 543
A5: Parameter | B5: Symbol | C5: Wert | D5: Einheit | E5: Bezug DIN EN 1992-1-1 / NA | F5: Anmerkung / Formel | R5: =C9 -> 3420 | S5: =C10 -> 600 | T5: =C9-C11 -> 3385 | U5: =C10-C11 -> 565 | V5: =IF(3<=$C$13,$C$33+(3-1)*($C$9-2*$C$33)/MAX($C$13-1,1),NA()) -> 791.66667 | W5: =IF(3<=$C$13,$C$33,NA()) -> 57
A6: Bemessungswert des Biegemoments | B6: M_Ed | C6: 250 | D6: kNm | E6: 6.1 | F6: Bemessungskombination GZT (EN 1990) | R6: =0 -> 0 | S6: =C10 -> 600 | T6: =C11 -> 35 | U6: =C10-C11 -> 565 | V6: =IF(4<=$C$13,$C$33+(4-1)*($C$9-2*$C$33)/MAX($C$13-1,1),NA()) -> 1159 | W6: =IF(4<=$C$13,$C$33,NA()) -> 57
A7: Bemessungswert der Querkraft | B7: V_Ed | C7: 200 | D7: kN | E7: 6.2.1 | R7: =0 -> 0 | S7: =0 -> 0 | T7: =C11 -> 35 | U7: =C11 -> 35 | V7: =IF(5<=$C$13,$C$33+(5-1)*($C$9-2*$C$33)/MAX($C$13-1,1),NA()) -> 1526.3333 | W7: =IF(5<=$C$13,$C$33,NA()) -> 57
A8: Bemessungswert des Torsionsmoments | B8: T_Ed | C8: 25 | D8: kNm | E8: 6.3.1 | V8: =IF(6<=$C$13,$C$33+(6-1)*($C$9-2*$C$33)/MAX($C$13-1,1),NA()) -> 1893.6667 | W8: =IF(6<=$C$13,$C$33,NA()) -> 57
A9: Querschnittsbreite | B9: b | C9: 3420 | D9: mm | E9: — | V9: =IF(7<=$C$13,$C$33+(7-1)*($C$9-2*$C$33)/MAX($C$13-1,1),NA()) -> 2261 | W9: =IF(7<=$C$13,$C$33,NA()) -> 57
A10: Gesamthöhe des Querschnitts | B10: h | C10: 600 | D10: mm | E10: — | V10: =IF(8<=$C$13,$C$33+(8-1)*($C$9-2*$C$33)/MAX($C$13-1,1),NA()) -> 2628.3333 | W10: =IF(8<=$C$13,$C$33,NA()) -> 57
A11: Nennmaß der Betondeckung | B11: c_nom | C11: 35 | D11: mm | E11: 4.4.1 / NA Tab. 4.4DE | V11: =IF(9<=$C$13,$C$33+(9-1)*($C$9-2*$C$33)/MAX($C$13-1,1),NA()) -> 2995.6667 | W11: =IF(9<=$C$13,$C$33,NA()) -> 57
A12: Durchmesser Längsstab | B12: Ø_l | C12: 20 | D12: mm | E12: — | V12: =IF(10<=$C$13,$C$33+(10-1)*($C$9-2*$C$33)/MAX($C$13-1,1),NA()) -> 3363 | W12: =IF(10<=$C$13,$C$33,NA()) -> 57
A13: Anzahl der Längsstäbe (Zugzone) | B13: n_l | C13: 10 | D13: — | E13: — | V13: =IF(11<=$C$13,$C$33+(11-1)*($C$9-2*$C$33)/MAX($C$13-1,1),NA()) -> #N/A | W13: =IF(11<=$C$13,$C$33,NA()) -> #N/A
A14: Durchmesser des Bügels | B14: Ø_w | C14: 12 | D14: mm | E14: 9.2.2 | V14: =IF(12<=$C$13,$C$33+(12-1)*($C$9-2*$C$33)/MAX($C$13-1,1),NA()) -> #N/A | W14: =IF(12<=$C$13,$C$33,NA()) -> #N/A
A15: Anzahl der Bügelschenkel (Querkraft) | B15: n_w | C15: 2 | D15: — | E15: 9.2.2
A16: Charakteristische Betondruckfestigkeit | B16: f_ck | C16: =_xlfn.XLOOKUP(F16,Aceros_DIN!$A$35:$A$43,Aceros_DIN!$B$35:$B$43) -> 30 | D16: N/mm² | E16: Tab. 3.1 | F16: C30/37
A17: Streckgrenze des Betonstahls | B17: f_yk | C17: =_xlfn.XLOOKUP(F17,Aceros_DIN!$A$47:$A$49,Aceros_DIN!$B$47:$B$49) -> 500 | D17: N/mm² | E17: 3.2.2 (B500) | F17: B500B
A18: Teilsicherheitsbeiwert Beton | B18: γ_c | C18: 1.5 | D18: — | E18: Tab. 2.1DE (NA)
A19: Teilsicherheitsbeiwert Betonstahl | B19: γ_s | C19: 1.15 | D19: — | E19: Tab. 2.1DE (NA)
A20: Beiwert Belastungsdauer k_tc | B20: k_tc | C20: 1 | D20: — | E20: §5.1.6(1) | F20: k_tc = 1,0 (Last ≥ 3 Monate nach Betonage) oder 0,85
A21: cot θ gewählt (0 = automatisch nach NA) | B21: cot θ | C21: 0 | D21: — | E21: NA 6.2.3(2), Gl. (6.7aDE)
A22: Abminderungsbeiwert Druckstrebe (Torsion) ν | B22: ν_T | C22: 0.6 | D22: — | E22: §8.3.4(3), Gl. (8.84) | F22: ν = 0,60 für cotθ = 1,0 (Anhang G für andere θ)
A24: 2. BAUSTOFFE
A25: Bemessungswert der Betondruckfestigkeit | B25: f_cd | C25: =MIN((40/C16)^(1/3),1)*C20*C16/C18 -> 20 | D25: N/mm² | E25: §5.1.6(1), Gl. (5.3)/(5.4) | F25: f_cd = η_cc·k_tc·f_ck/γ_C ; η_cc=(40/f_ck)^⅓≤1,0 (f_ck,ref=40 MPa)
A26: Mittlere Betonzugfestigkeit | B26: f_ctm | C26: =0.3*C16^(2/3) -> 2.8964682 | D26: N/mm² | E26: Tab. 5.1 | F26: f_ctm = 0,30·f_ck^(2/3) für ≤ C50/60
A27: Bemessungswert der Betonzugfestigkeit | B27: f_ctd | C27: =C20*0.7*C26/C18 -> 1.3516851 | D27: N/mm² | E27: §5.1.6(1) | F27: f_ctd = k_tc·0,7·f_ctm/γ_C (f_ctk;0,05 = 0,7·f_ctm)
A28: Bemessungswert der Stahlstreckgrenze | B28: f_yd | C28: =C17/C19 -> 434.78261 | D28: N/mm² | E28: §5.2.4, Bild 5.4 | F28: f_yd = f_yk/γ_s
A29: Grenzdehnung des Betons | B29: ε_cu2 | C29: 0.0035 | D29: — | E29: Tab. 5.1 / §8.1.2
A30: Bemessungswert der Fließdehnung des Stahls | B30: ε_yd | C30: =C28/200000 -> 0.002173913 | D30: — | E30: §5.2.4 | F30: ε_yd = f_yd/E_s ; E_s = 200 000 N/mm²
A32: 3. QUERSCHNITTSGEOMETRIE UND ÄQUIVALENTER HOHLKASTEN (Torsion)
A33: Randabstand bis zum Schwerpunkt der Bewehrung | B33: d₁ | C33: =C11+C14+C12/2 -> 57 | D33: mm | E33: 4.4.1 | F33: d₁ = c_nom + Ø_w + Ø_l/2
A34: Statische Nutzhöhe | B34: d | C34: =C10-C33 -> 543 | D34: mm | E34: 6.1 | F34: d = h − d₁
A35: Betonquerschnittsfläche | B35: A_c | C35: =C9*C10 -> 2052000 | D35: mm² | E35: — | F35: A_c = b·h
A36: Vorhandene Längszugbewehrung | B36: A_s,vorh | C36: =C13*PI()*C12^2/4 -> 3141.5927 | D36: mm² | E36: — | F36: A_s,vorh = n_l·π·Ø_l²/4
A37: Äußerer Umfang des Querschnitts | B37: u | C37: =2*(C9+C10) -> 8040 | D37: mm | E37: 6.3.2(1) | F37: u = 2·(b+h)
A38: Wirksame Wanddicke | B38: t_ef | C38: =MAX(C35/C37,2*C33) -> 255.22388 | D38: mm | E38: 6.3.2(1) | F38: t_ef = A/u , aber ≥ 2·d₁ (Deckung bis Stabmitte)
A39: Von der Mittellinie umschlossene Fläche | B39: A_k | C39: =(C9-C38)*(C10-C38) -> 1091139.2 | D39: mm² | E39: 6.3.2(1) | F39: A_k = (b−t_ef)·(h−t_ef)
A40: Umfang der Mittellinie | B40: u_k | C40: =2*((C9-C38)+(C10-C38)) -> 7019.1045 | D40: mm | E40: 6.3.2(1) | F40: u_k = 2·((b−t_ef)+(h−t_ef))
A41: Innerer Hebelarm (Querkraft/Torsion) | B41: z | C41: =0.9*C34 -> 488.7 | D41: mm | E41: 6.2.3(1) | F41: z ≈ 0,9·d
A43: 4. BIEGEBEMESSUNG — LÄNGSBEWEHRUNG (μ–ξ–ω-Verfahren)
...

Sheet Pfahl_DIN
A1: BEMESSUNG DER PFAHLBEWEHRUNG — KREISQUERSCHNITT AUS STAHLBETON
A2: DIN EN 1992-1-1:2011 (EC2) + DIN EN 1992-1-1/NA:2013 (Nationaler Anhang) · Konstruktive Durchbildung: DIN EN 1536 (Bohrpfähle) | Q2: Ángulo | R2: Contorno X | S2: Contorno Y | T2: Espiral X | U2: Espiral Y | V2: Barras X | W2: Barras Y
Q3: =(ROW()-3)*10 -> 0 | R3: =$C$34+$C$34*COS(RADIANS(Q3)) -> 600 | S3: =$C$34+$C$34*SIN(RADIANS(Q3)) -> 300 | T3: =$C$34+($C$34-$C$10)*COS(RADIANS(Q3)) -> 550 | U3: =$C$34+($C$34-$C$10)*SIN(RADIANS(Q3)) -> 300 | V3: =IF(ROW()-2<=$C$11,$C$34+$C$37*COS(RADIANS((ROW()-3)*360/$C$11)),NA()) -> 530 | W3: =IF(ROW()-2<=$C$11,$C$34+$C$37*SIN(RADIANS((ROW()-3)*360/$C$11)),NA()) -> 300
A4: 1. EINGABEDATEN (blaue Zellen = editierbar) | Q4: =(ROW()-3)*10 -> 10 | R4: =$C$34+$C$34*COS(RADIANS(Q4)) -> 595.44233 | S4: =$C$34+$C$34*SIN(RADIANS(Q4)) -> 352.09445 | T4: =$C$34+($C$34-$C$10)*COS(RADIANS(Q4)) -> 546.20194 | U4: =$C$34+($C$34-$C$10)*SIN(RADIANS(Q4)) -> 343.41204 | V4: =IF(ROW()-2<=$C$11,$C$34+$C$37*COS(RADIANS((ROW()-3)*360/$C$11)),NA()) -> 462.63456 | W4: =IF(ROW()-2<=$C$11,$C$34+$C$37*SIN(RADIANS((ROW()-3)*360/$C$11)),NA()) -> 462.63456
A5: Parameter | B5: Symbol | C5: Wert | D5: Einheit | E5: Bezug DIN EN 1992-1-1 / NA | F5: Anmerkung | Q5: =(ROW()-3)*10 -> 20 | R5: =$C$34+$C$34*COS(RADIANS(Q5)) -> 581.90779 | S5: =$C$34+$C$34*SIN(RADIANS(Q5)) -> 402.60604 | T5: =$C$34+($C$34-$C$10)*COS(RADIANS(Q5)) -> 534.92316 | U5: =$C$34+($C$34-$C$10)*SIN(RADIANS(Q5)) -> 385.50504 | V5: =IF(ROW()-2<=$C$11,$C$34+$C$37*COS(RADIANS((ROW()-3)*360/$C$11)),NA()) -> 300 | W5: =IF(ROW()-2<=$C$11,$C$34+$C$37*SIN(RADIANS((ROW()-3)*360/$C$11)),NA()) -> 530
A6: Bemessungswert der Normalkraft (Druck positiv) | B6: N_Ed | C6: 1000 | D6: kN | E6: 6.1 | F6: Bemessungskombination GZT (EN 1990) | Q6: =(ROW()-3)*10 -> 30 | R6: =$C$34+$C$34*COS(RADIANS(Q6)) -> 559.80762 | S6: =$C$34+$C$34*SIN(RADIANS(Q6)) -> 450 | T6: =$C$34+($C$34-$C$10)*COS(RADIANS(Q6)) -> 516.50635 | U6: =$C$34+($C$34-$C$10)*SIN(RADIANS(Q6)) -> 425 | V6: =IF(ROW()-2<=$C$11,$C$34+$C$37*COS(RADIANS((ROW()-3)*360/$C$11)),NA()) -> 137.36544 | W6: =IF(ROW()-2<=$C$11,$C$34+$C$37*SIN(RADIANS((ROW()-3)*360/$C$11)),NA()) -> 462.63456
A7: Bemessungswert der Querkraft | B7: V_Ed | C7: 300 | D7: kN | E7: 6.2.1 | Q7: =(ROW()-3)*10 -> 40 | R7: =$C$34+$C$34*COS(RADIANS(Q7)) -> 529.81333 | S7: =$C$34+$C$34*SIN(RADIANS(Q7)) -> 492.83628 | T7: =$C$34+($C$34-$C$10)*COS(RADIANS(Q7)) -> 491.51111 | U7: =$C$34+($C$34-$C$10)*SIN(RADIANS(Q7)) -> 460.6969 | V7: =IF(ROW()-2<=$C$11,$C$34+$C$37*COS(RADIANS((ROW()-3)*360/$C$11)),NA()) -> 70 | W7: =IF(ROW()-2<=$C$11,$C$34+$C$37*SIN(RADIANS((ROW()-3)*360/$C$11)),NA()) -> 300
A8: Bemessungswert des Moments im Schnitt (1. Ordnung) | B8: M_Ed | C8: 300 | D8: kNm | E8: 6.1 | Q8: =(ROW()-3)*10 -> 50 | R8: =$C$34+$C$34*COS(RADIANS(Q8)) -> 492.83628 | S8: =$C$34+$C$34*SIN(RADIANS(Q8)) -> 529.81333 | T8: =$C$34+($C$34-$C$10)*COS(RADIANS(Q8)) -> 460.6969 | U8: =$C$34+($C$34-$C$10)*SIN(RADIANS(Q8)) -> 491.51111 | V8: =IF(ROW()-2<=$C$11,$C$34+$C$37*COS(RADIANS((ROW()-3)*360/$C$11)),NA()) -> 137.36544 | W8: =IF(ROW()-2<=$C$11,$C$34+$C$37*SIN(RADIANS((ROW()-3)*360/$C$11)),NA()) -> 137.36544
A9: Pfahldurchmesser | B9: D = h | C9: 600 | D9: mm | E9: DIN EN 1536, 7.5 | Q9: =(ROW()-3)*10 -> 60 | R9: =$C$34+$C$34*COS(RADIANS(Q9)) -> 450 | S9: =$C$34+$C$34*SIN(RADIANS(Q9)) -> 559.80762 | T9: =$C$34+($C$34-$C$10)*COS(RADIANS(Q9)) -> 425 | U9: =$C$34+($C$34-$C$10)*SIN(RADIANS(Q9)) -> 516.50635 | V9: =IF(ROW()-2<=$C$11,$C$34+$C$37*COS(RADIANS((ROW()-3)*360/$C$11)),NA()) -> 300 | W9: =IF(ROW()-2<=$C$11,$C$34+$C$37*SIN(RADIANS((ROW()-3)*360/$C$11)),NA()) -> 70
A10: Nennmaß der Betondeckung | B10: c_nom | C10: 50 | D10: mm | E10: 4.4.1.1 / NA Tab. 4.4DE | Q10: =(ROW()-3)*10 -> 70 | R10: =$C$34+$C$34*COS(RADIANS(Q10)) -> 402.60604 | S10: =$C$34+$C$34*SIN(RADIANS(Q10)) -> 581.90779 | T10: =$C$34+($C$34-$C$10)*COS(RADIANS(Q10)) -> 385.50504 | U10: =$C$34+($C$34-$C$10)*SIN(RADIANS(Q10)) -> 534.92316 | V10: =IF(ROW()-2<=$C$11,$C$34+$C$37*COS(RADIANS((ROW()-3)*360/$C$11)),NA()) -> 462.63456 | W10: =IF(ROW()-2<=$C$11,$C$34+$C$37*SIN(RADIANS((ROW()-3)*360/$C$11)),NA()) -> 137.36544
A11: Anzahl der Längsbewehrungsstäbe | B11: n_l | C11: 8 | D11: - | E11: 9.8.5(3) | F11: ≥ 6 Stäbe | Q11: =(ROW()-3)*10 -> 80 | R11: =$C$34+$C$34*COS(RADIANS(Q11)) -> 352.09445 | S11: =$C$34+$C$34*SIN(RADIANS(Q11)) -> 595.44233 | T11: =$C$34+($C$34-$C$10)*COS(RADIANS(Q11)) -> 343.41204 | U11: =$C$34+($C$34-$C$10)*SIN(RADIANS(Q11)) -> 546.20194 | V11: =IF(ROW()-2<=$C$11,$C$34+$C$37*COS(RADIANS((ROW()-3)*360/$C$11)),NA()) -> #N/A | W11: =IF(ROW()-2<=$C$11,$C$34+$C$37*SIN(RADIANS((ROW()-3)*360/$C$11)),NA()) -> #N/A
A12: Durchmesser Längsstab | B12: Ø_l | C12: 20 | D12: mm | E12: 9.8.5(3) | F12: ≥ 16 mm | Q12: =(ROW()-3)*10 -> 90 | R12: =$C$34+$C$34*COS(RADIANS(Q12)) -> 300 | S12: =$C$34+$C$34*SIN(RADIANS(Q12)) -> 600 | T12: =$C$34+($C$34-$C$10)*COS(RADIANS(Q12)) -> 300 | U12: =$C$34+($C$34-$C$10)*SIN(RADIANS(Q12)) -> 550 | V12: =IF(ROW()-2<=$C$11,$C$34+$C$37*COS(RADIANS((ROW()-3)*360/$C$11)),NA()) -> #N/A | W12: =IF(ROW()-2<=$C$11,$C$34+$C$37*SIN(RADIANS((ROW()-3)*360/$C$11)),NA()) -> #N/A
A13: Durchmesser Wendel/Bügel | B13: Ø_w | C13: 10 | D13: mm | E13: DIN EN 1536, 7.5.2 | F13: ≥ 6 mm | Q13: =(ROW()-3)*10 -> 100 | R13: =$C$34+$C$34*COS(RADIANS(Q13)) -> 247.90555 | S13: =$C$34+$C$34*SIN(RADIANS(Q13)) -> 595.44233 | T13: =$C$34+($C$34-$C$10)*COS(RADIANS(Q13)) -> 256.58796 | U13: =$C$34+($C$34-$C$10)*SIN(RADIANS(Q13)) -> 546.20194 | V13: =IF(ROW()-2<=$C$11,$C$34+$C$37*COS(RADIANS((ROW()-3)*360/$C$11)),NA()) -> #N/A | W13: =IF(ROW()-2<=$C$11,$C$34+$C$37*SIN(RADIANS((ROW()-3)*360/$C$11)),NA()) -> #N/A
A14: Gewählte Ganghöhe der Wendel | B14: s_w | C14: 150 | D14: mm | E14: 9.2.2(6) / NA | Q14: =(ROW()-3)*10 -> 110 | R14: =$C$34+$C$34*COS(RADIANS(Q14)) -> 197.39396 | S14: =$C$34+$C$34*SIN(RADIANS(Q14)) -> 581.90779 | T14: =$C$34+($C$34-$C$10)*COS(RADIANS(Q14)) -> 214.49496 | U14: =$C$34+($C$34-$C$10)*SIN(RADIANS(Q14)) -> 534.92316 | V14: =IF(ROW()-2<=$C$11,$C$34+$C$37*COS(RADIANS((ROW()-3)*360/$C$11)),NA()) -> #N/A | W14: =IF(ROW()-2<=$C$11,$C$34+$C$37*SIN(RADIANS((ROW()-3)*360/$C$11)),NA()) -> #N/A
A15: Charakteristische Betondruckfestigkeit | B15: f_ck | C15: =_xlfn.XLOOKUP(F15,Aceros_DIN!$A$35:$A$43,Aceros_DIN!$B$35:$B$43) -> 25 | D15: N/mm² | E15: Tab. 3.1 | F15: C25/30 | Q15: =(ROW()-3)*10 -> 120 | R15: =$C$34+$C$34*COS(RADIANS(Q15)) -> 150 | S15: =$C$34+$C$34*SIN(RADIANS(Q15)) -> 559.80762 | T15: =$C$34+($C$34-$C$10)*COS(RADIANS(Q15)) -> 175 | U15: =$C$34+($C$34-$C$10)*SIN(RADIANS(Q15)) -> 516.50635 | V15: =IF(ROW()-2<=$C$11,$C$34+$C$37*COS(RADIANS((ROW()-3)*360/$C$11)),NA()) -> #N/A | W15: =IF(ROW()-2<=$C$11,$C$34+$C$37*SIN(RADIANS((ROW()-3)*360/$C$11)),NA()) -> #N/A
A16: Streckgrenze des Betonstahls | B16: f_yk | C16: =_xlfn.XLOOKUP(F16,Aceros_DIN!$A$47:$A$49,Aceros_DIN!$B$47:$B$49) -> 500 | D16: N/mm² | E16: 3.2.2 (B500) | F16: B500B | Q16: =(ROW()-3)*10 -> 130 | R16: =$C$34+$C$34*COS(RADIANS(Q16)) -> 107.16372 | S16: =$C$34+$C$34*SIN(RADIANS(Q16)) -> 529.81333 | T16: =$C$34+($C$34-$C$10)*COS(RADIANS(Q16)) -> 139.3031 | U16: =$C$34+($C$34-$C$10)*SIN(RADIANS(Q16)) -> 491.51111 | V16: =IF(ROW()-2<=$C$11,$C$34+$C$37*COS(RADIANS((ROW()-3)*360/$C$11)),NA()) -> #N/A | W16: =IF(ROW()-2<=$C$11,$C$34+$C$37*SIN(RADIANS((ROW()-3)*360/$C$11)),NA()) -> #N/A
A17: Teilsicherheitsbeiwert Beton | B17: γ_c | C17: 1.5 | D17: - | E17: Tab. 2.1DE (NA) | Q17: =(ROW()-3)*10 -> 140 | R17: =$C$34+$C$34*COS(RADIANS(Q17)) -> 70.186667 | S17: =$C$34+$C$34*SIN(RADIANS(Q17)) -> 492.83628 | T17: =$C$34+($C$34-$C$10)*COS(RADIANS(Q17)) -> 108.48889 | U17: =$C$34+($C$34-$C$10)*SIN(RADIANS(Q17)) -> 460.6969 | V17: =IF(ROW()-2<=$C$11,$C$34+$C$37*COS(RADIANS((ROW()-3)*360/$C$11)),NA()) -> #N/A | W17: =IF(ROW()-2<=$C$11,$C$34+$C$37*SIN(RADIANS((ROW()-3)*360/$C$11)),NA()) -> #N/A
A18: Teilsicherheitsbeiwert Betonstahl | B18: γ_s | C18: 1.15 | D18: - | E18: Tab. 2.1DE (NA) | Q18: =(ROW()-3)*10 -> 150 | R18: =$C$34+$C$34*COS(RADIANS(Q18)) -> 40.192379 | S18: =$C$34+$C$34*SIN(RADIANS(Q18)) -> 450 | T18: =$C$34+($C$34-$C$10)*COS(RADIANS(Q18)) -> 83.493649 | U18: =$C$34+($C$34-$C$10)*SIN(RADIANS(Q18)) -> 425 | V18: =IF(ROW()-2<=$C$11,$C$34+$C$37*COS(RADIANS((ROW()-3)*360/$C$11)),NA()) -> #N/A | W18: =IF(ROW()-2<=$C$11,$C$34+$C$37*SIN(RADIANS((ROW()-3)*360/$C$11)),NA()) -> #N/A
A19: Beiwert Dauerstandeinfluss | B19: α_cc | C19: 0.85 | D19: - | E19: NA 3.1.6(1) | Q19: =(ROW()-3)*10 -> 160 | R19: =$C$34+$C$34*COS(RADIANS(Q19)) -> 18.092214 | S19: =$C$34+$C$34*SIN(RADIANS(Q19)) -> 402.60604 | T19: =$C$34+($C$34-$C$10)*COS(RADIANS(Q19)) -> 65.076845 | U19: =$C$34+($C$34-$C$10)*SIN(RADIANS(Q19)) -> 385.50504 | V19: =IF(ROW()-2<=$C$11,$C$34+$C$37*COS(RADIANS((ROW()-3)*360/$C$11)),NA()) -> #N/A | W19: =IF(ROW()-2<=$C$11,$C$34+$C$37*SIN(RADIANS((ROW()-3)*360/$C$11)),NA()) -> #N/A
A20: Knicklänge (0 = Theorie II. Ordnung nicht ansetzen) | B20: l_0 | C20: 3000 | D20: mm | E20: 5.8.3.2 | Q20: =(ROW()-3)*10 -> 170 | R20: =$C$34+$C$34*COS(RADIANS(Q20)) -> 4.5576741 | S20: =$C$34+$C$34*SIN(RADIANS(Q20)) -> 352.09445 | T20: =$C$34+($C$34-$C$10)*COS(RADIANS(Q20)) -> 53.798062 | U20: =$C$34+($C$34-$C$10)*SIN(RADIANS(Q20)) -> 343.41204 | V20: =IF(ROW()-2<=$C$11,$C$34+$C$37*COS(RADIANS((ROW()-3)*360/$C$11)),NA()) -> #N/A | W20: =IF(ROW()-2<=$C$11,$C$34+$C$37*SIN(RADIANS((ROW()-3)*360/$C$11)),NA()) -> #N/A
A21: cot θ gewählt (0 = automatisch nach NA) | B21: cot θ | C21: 0 | D21: - | E21: NA 6.2.3(2), ec. (6.7aDE) | Q21: =(ROW()-3)*10 -> 180 | R21: =$C$34+$C$34*COS(RADIANS(Q21)) -> 0 | S21: =$C$34+$C$34*SIN(RADIANS(Q21)) -> 300 | T21: =$C$34+($C$34-$C$10)*COS(RADIANS(Q21)) -> 50 | U21: =$C$34+($C$34-$C$10)*SIN(RADIANS(Q21)) -> 300 | V21: =IF(ROW()-2<=$C$11,$C$34+$C$37*COS(RADIANS((ROW()-3)*360/$C$11)),NA()) -> #N/A | W21: =IF(ROW()-2<=$C$11,$C$34+$C$37*SIN(RADIANS((ROW()-3)*360/$C$11)),NA()) -> #N/A
Q22: =(ROW()-3)*10 -> 190 | R22: =$C$34+$C$34*COS(RADIANS(Q22)) -> 4.5576741 | S22: =$C$34+$C$34*SIN(RADIANS(Q22)) -> 247.90555 | T22: =$C$34+($C$34-$C$10)*COS(RADIANS(Q22)) -> 53.798062 | U22: =$C$34+($C$34-$C$10)*SIN(RADIANS(Q22)) -> 256.58796 | V22: =IF(ROW()-2<=$C$11,$C$34+$C$37*COS(RADIANS((ROW()-3)*360/$C$11)),NA()) -> #N/A | W22: =IF(ROW()-2<=$C$11,$C$34+$C$37*SIN(RADIANS((ROW()-3)*360/$C$11)),NA()) -> #N/A
A23: 2. BAUSTOFFE | Q23: =(ROW()-3)*10 -> 200 | R23: =$C$34+$C$34*COS(RADIANS(Q23)) -> 18.092214 | S23: =$C$34+$C$34*SIN(RADIANS(Q23)) -> 197.39396 | T23: =$C$34+($C$34-$C$10)*COS(RADIANS(Q23)) -> 65.076845 | U23: =$C$34+($C$34-$C$10)*SIN(RADIANS(Q23)) -> 214.49496 | V23: =IF(ROW()-2<=$C$11,$C$34+$C$37*COS(RADIANS((ROW()-3)*360/$C$11)),NA()) -> #N/A | W23: =IF(ROW()-2<=$C$11,$C$34+$C$37*SIN(RADIANS((ROW()-3)*360/$C$11)),NA()) -> #N/A
A24: Bemessungswert der Betondruckfestigkeit | B24: f_cd | C24: =C19*C15/C17 -> 14.166667 | D24: N/mm² | E24: 3.1.6(1), Gl. (3.15) | F24: f_cd = α_cc · f_ck / γ_c | Q24: =(ROW()-3)*10 -> 210 | R24: =$C$34+$C$34*COS(RADIANS(Q24)) -> 40.192379 | S24: =$C$34+$C$34*SIN(RADIANS(Q24)) -> 150 | T24: =$C$34+($C$34-$C$10)*COS(RADIANS(Q24)) -> 83.493649 | U24: =$C$34+($C$34-$C$10)*SIN(RADIANS(Q24)) -> 175 | V24: =IF(ROW()-2<=$C$11,$C$34+$C$37*COS(RADIANS((ROW()-3)*360/$C$11)),NA()) -> #N/A | W24: =IF(ROW()-2<=$C$11,$C$34+$C$37*SIN(RADIANS((ROW()-3)*360/$C$11)),NA()) -> #N/A
A25: Mittlere Betonzugfestigkeit | B25: f_ctm | C25: =IF(C15<=50,0.3*C15^(2/3),2.12*LN(1+(C15+8)/10)) -> 2.5649639 | D25: N/mm² | E25: Tab. 3.1 | Q25: =(ROW()-3)*10 -> 220 | R25: =$C$34+$C$34*COS(RADIANS(Q25)) -> 70.186667 | S25: =$C$34+$C$34*SIN(RADIANS(Q25)) -> 107.16372 | T25: =$C$34+($C$34-$C$10)*COS(RADIANS(Q25)) -> 108.48889 | U25: =$C$34+($C$34-$C$10)*SIN(RADIANS(Q25)) -> 139.3031 | V25: =IF(ROW()-2<=$C$11,$C$34+$C$37*COS(RADIANS((ROW()-3)*360/$C$11)),NA()) -> #N/A | W25: =IF(ROW()-2<=$C$11,$C$34+$C$37*SIN(RADIANS((ROW()-3)*360/$C$11)),NA()) -> #N/A
A26: Bemessungswert der Stahlstreckgrenze | B26: f_yd | C26: =C16/C18 -> 434.78261 | D26: N/mm² | E26: 3.2.7(2), Bild 3.8 | Q26: =(ROW()-3)*10 -> 230 | R26: =$C$34+$C$34*COS(RADIANS(Q26)) -> 107.16372 | S26: =$C$34+$C$34*SIN(RADIANS(Q26)) -> 70.186667 | T26: =$C$34+($C$34-$C$10)*COS(RADIANS(Q26)) -> 139.3031 | U26: =$C$34+($C$34-$C$10)*SIN(RADIANS(Q26)) -> 108.48889 | V26: =IF(ROW()-2<=$C$11,$C$34+$C$37*COS(RADIANS((ROW()-3)*360/$C$11)),NA()) -> #N/A | W26: =IF(ROW()-2<=$C$11,$C$34+$C$37*SIN(RADIANS((ROW()-3)*360/$C$11)),NA()) -> #N/A
A27: Elastizitätsmodul Betonstahl | B27: E_s | C27: 200000 | D27: N/mm² | E27: 3.2.7(4) | Q27: =(ROW()-3)*10 -> 240 | R27: =$C$34+$C$34*COS(RADIANS(Q27)) -> 150 | S27: =$C$34+$C$34*SIN(RADIANS(Q27)) -> 40.192379 | T27: =$C$34+($C$34-$C$10)*COS(RADIANS(Q27)) -> 175 | U27: =$C$34+($C$34-$C$10)*SIN(RADIANS(Q27)) -> 83.493649
A28: Bemessungswert der Fließdehnung | B28: ε_yd | C28: =C26/C27 -> 0.002173913 | D28: - | E28: 3.2.7(2) | Q28: =(ROW()-3)*10 -> 250 | R28: =$C$34+$C$34*COS(RADIANS(Q28)) -> 197.39396 | S28: =$C$34+$C$34*SIN(RADIANS(Q28)) -> 18.092214 | T28: =$C$34+($C$34-$C$10)*COS(RADIANS(Q28)) -> 214.49496 | U28: =$C$34+($C$34-$C$10)*SIN(RADIANS(Q28)) -> 65.076845
A29: Grenzdehnung des Betons (Biegung) | B29: ε_cu2 | C29: 3.5 | D29: ‰ | E29: Tab. 3.1 / 3.1.7(3) | Q29: =(ROW()-3)*10 -> 260 | R29: =$C$34+$C$34*COS(RADIANS(Q29)) -> 247.90555 | S29: =$C$34+$C$34*SIN(RADIANS(Q29)) -> 4.5576741 | T29: =$C$34+($C$34-$C$10)*COS(RADIANS(Q29)) -> 256.58796 | U29: =$C$34+($C$34-$C$10)*SIN(RADIANS(Q29)) -> 53.798062
A30: Stauchung bei zentrischem Druck | B30: ε_c2 | C30: 2 | D30: ‰ | E30: Tab. 3.1 (Punkt C, Bild 6.1) | Q30: =(ROW()-3)*10 -> 270 | R30: =$C$34+$C$34*COS(RADIANS(Q30)) -> 300 | S30: =$C$34+$C$34*SIN(RADIANS(Q30)) -> 0 | T30: =$C$34+($C$34-$C$10)*COS(RADIANS(Q30)) -> 300 | U30: =$C$34+($C$34-$C$10)*SIN(RADIANS(Q30)) -> 50
A31: Grenzdehnung des Betonstahls | B31: ε_ud | C31: 25 | D31: ‰ | E31: NA 3.2.7(2): ε_ud = 25 ‰ | Q31: =(ROW()-3)*10 -> 280 | R31: =$C$34+$C$34*COS(RADIANS(Q31)) -> 352.09445 | S31: =$C$34+$C$34*SIN(RADIANS(Q31)) -> 4.5576741 | T31: =$C$34+($C$34-$C$10)*COS(RADIANS(Q31)) -> 343.41204 | U31: =$C$34+($C$34-$C$10)*SIN(RADIANS(Q31)) -> 53.798062
Q32: =(ROW()-3)*10 -> 290 | R32: =$C$34+$C$34*COS(RADIANS(Q32)) -> 402.60604 | S32: =$C$34+$C$34*SIN(RADIANS(Q32)) -> 18.092214 | T32: =$C$34+($C$34-$C$10)*COS(RADIANS(Q32)) -> 385.50504 | U32: =$C$34+($C$34-$C$10)*SIN(RADIANS(Q32)) -> 65.076845
A33: 3. QUERSCHNITTSGEOMETRIE | Q33: =(ROW()-3)*10 -> 300 | R33: =$C$34+$C$34*COS(RADIANS(Q33)) -> 450 | S33: =$C$34+$C$34*SIN(RADIANS(Q33)) -> 40.192379 | T33: =$C$34+($C$34-$C$10)*COS(RADIANS(Q33)) -> 425 | U33: =$C$34+($C$34-$C$10)*SIN(RADIANS(Q33)) -> 83.493649
A34: Außenradius | B34: r | C34: =C9/2 -> 300 | D34: mm | Q34: =(ROW()-3)*10 -> 310 | R34: =$C$34+$C$34*COS(RADIANS(Q34)) -> 492.83628 | S34: =$C$34+$C$34*SIN(RADIANS(Q34)) -> 70.186667 | T34: =$C$34+($C$34-$C$10)*COS(RADIANS(Q34)) -> 460.6969 | U34: =$C$34+($C$34-$C$10)*SIN(RADIANS(Q34)) -> 108.48889
A35: Betonquerschnittsfläche | B35: A_c | C35: =PI()*C9^2/4 -> 282743.34 | D35: mm² | Q35: =(ROW()-3)*10 -> 320 | R35: =$C$34+$C$34*COS(RADIANS(Q35)) -> 529.81333 | S35: =$C$34+$C$34*SIN(RADIANS(Q35)) -> 107.16372 | T35: =$C$34+($C$34-$C$10)*COS(RADIANS(Q35)) -> 491.51111 | U35: =$C$34+($C$34-$C$10)*SIN(RADIANS(Q35)) -> 139.3031
A36: Achsabstand Bewehrung vom Rand | B36: d_1 | C36: =C10+C13+C12/2 -> 70 | D36: mm | E36: 4.4.1 | Q36: =(ROW()-3)*10 -> 330 | R36: =$C$34+$C$34*COS(RADIANS(Q36)) -> 559.80762 | S36: =$C$34+$C$34*SIN(RADIANS(Q36)) -> 150 | T36: =$C$34+($C$34-$C$10)*COS(RADIANS(Q36)) -> 516.50635 | U36: =$C$34+($C$34-$C$10)*SIN(RADIANS(Q36)) -> 175
A37: Radius des Bewehrungskreises | B37: r_s | C37: =C34-C36 -> 230 | D37: mm | Q37: =(ROW()-3)*10 -> 340 | R37: =$C$34+$C$34*COS(RADIANS(Q37)) -> 581.90779 | S37: =$C$34+$C$34*SIN(RADIANS(Q37)) -> 197.39396 | T37: =$C$34+($C$34-$C$10)*COS(RADIANS(Q37)) -> 534.92316 | U37: =$C$34+($C$34-$C$10)*SIN(RADIANS(Q37)) -> 214.49496
A38: Rechnerische Nutzhöhe für Querkraft | B38: d | C38: =C34+2*C37/PI() -> 446.42255 | D38: mm | E38: 6.2.1 / DAfStb-Heft 600 | Q38: =(ROW()-3)*10 -> 350 | R38: =$C$34+$C$34*COS(RADIANS(Q38)) -> 595.44233 | S38: =$C$34+$C$34*SIN(RADIANS(Q38)) -> 247.90555 | T38: =$C$34+($C$34-$C$10)*COS(RADIANS(Q38)) -> 546.20194 | U38: =$C$34+($C$34-$C$10)*SIN(RADIANS(Q38)) -> 256.58796
A39: Innerer Hebelarm für Querkraft | B39: z | C39: =0.9*C38 -> 401.78029 | D39: mm | E39: 6.2.3(1) | Q39: =(ROW()-3)*10 -> 360 | R39: =$C$34+$C$34*COS(RADIANS(Q39)) -> 600 | S39: =$C$34+$C$34*SIN(RADIANS(Q39)) -> 300 | T39: =$C$34+($C$34-$C$10)*COS(RADIANS(Q39)) -> 550 | U39: =$C$34+($C$34-$C$10)*SIN(RADIANS(Q39)) -> 300
A40: Vorhandene Längsbewehrungsfläche | B40: A_s,prov | C40: =C11*PI()*C12^2/4 -> 2513.2741 | D40: mm²
...

Sheet Pfahl_2025
A1: BEMESSUNG DER PFAHLBEWEHRUNG — KREISQUERSCHNITT AUS STAHLBETON
A2: DIN EN 1992-1-1:2025 (EC2) + DIN EN 1992-1-1/NA1:2025 · Kreisquerschnitt aus Stahlbeton · Bemessung DIN EN 1536 (Bohrpfähle) | Q2: Ángulo | R2: Contorno X | S2: Contorno Y | T2: Espiral X | U2: Espiral Y | V2: Barras X | W2: Barras Y
Q3: =(ROW()-3)*10 -> 0 | R3: =$C$34+$C$34*COS(RADIANS(Q3)) -> 600 | S3: =$C$34+$C$34*SIN(RADIANS(Q3)) -> 300 | T3: =$C$34+($C$34-$C$10)*COS(RADIANS(Q3)) -> 550 | U3: =$C$34+($C$34-$C$10)*SIN(RADIANS(Q3)) -> 300 | V3: =IF(ROW()-2<=$C$11,$C$34+$C$37*COS(RADIANS((ROW()-3)*360/$C$11)),NA()) -> 530 | W3: =IF(ROW()-2<=$C$11,$C$34+$C$37*SIN(RADIANS((ROW()-3)*360/$C$11)),NA()) -> 300
A4: 1. EINGABEDATEN (blaue Zellen = editierbar) | Q4: =(ROW()-3)*10 -> 10 | R4: =$C$34+$C$34*COS(RADIANS(Q4)) -> 595.44233 | S4: =$C$34+$C$34*SIN(RADIANS(Q4)) -> 352.09445 | T4: =$C$34+($C$34-$C$10)*COS(RADIANS(Q4)) -> 546.20194 | U4: =$C$34+($C$34-$C$10)*SIN(RADIANS(Q4)) -> 343.41204 | V4: =IF(ROW()-2<=$C$11,$C$34+$C$37*COS(RADIANS((ROW()-3)*360/$C$11)),NA()) -> 462.63456 | W4: =IF(ROW()-2<=$C$11,$C$34+$C$37*SIN(RADIANS((ROW()-3)*360/$C$11)),NA()) -> 462.63456
A5: Parameter | B5: Symbol | C5: Wert | D5: Einheit | E5: Bezug DIN EN 1992-1-1 / NA | F5: Anmerkung | Q5: =(ROW()-3)*10 -> 20 | R5: =$C$34+$C$34*COS(RADIANS(Q5)) -> 581.90779 | S5: =$C$34+$C$34*SIN(RADIANS(Q5)) -> 402.60604 | T5: =$C$34+($C$34-$C$10)*COS(RADIANS(Q5)) -> 534.92316 | U5: =$C$34+($C$34-$C$10)*SIN(RADIANS(Q5)) -> 385.50504 | V5: =IF(ROW()-2<=$C$11,$C$34+$C$37*COS(RADIANS((ROW()-3)*360/$C$11)),NA()) -> 300 | W5: =IF(ROW()-2<=$C$11,$C$34+$C$37*SIN(RADIANS((ROW()-3)*360/$C$11)),NA()) -> 530
A6: Bemessungswert der Normalkraft (Druck positiv) | B6: N_Ed | C6: 1000 | D6: kN | E6: 6.1 | F6: Bemessungskombination GZT (EN 1990) | Q6: =(ROW()-3)*10 -> 30 | R6: =$C$34+$C$34*COS(RADIANS(Q6)) -> 559.80762 | S6: =$C$34+$C$34*SIN(RADIANS(Q6)) -> 450 | T6: =$C$34+($C$34-$C$10)*COS(RADIANS(Q6)) -> 516.50635 | U6: =$C$34+($C$34-$C$10)*SIN(RADIANS(Q6)) -> 425 | V6: =IF(ROW()-2<=$C$11,$C$34+$C$37*COS(RADIANS((ROW()-3)*360/$C$11)),NA()) -> 137.36544 | W6: =IF(ROW()-2<=$C$11,$C$34+$C$37*SIN(RADIANS((ROW()-3)*360/$C$11)),NA()) -> 462.63456
A7: Bemessungswert der Querkraft | B7: V_Ed | C7: 300 | D7: kN | E7: 6.2.1 | Q7: =(ROW()-3)*10 -> 40 | R7: =$C$34+$C$34*COS(RADIANS(Q7)) -> 529.81333 | S7: =$C$34+$C$34*SIN(RADIANS(Q7)) -> 492.83628 | T7: =$C$34+($C$34-$C$10)*COS(RADIANS(Q7)) -> 491.51111 | U7: =$C$34+($C$34-$C$10)*SIN(RADIANS(Q7)) -> 460.6969 | V7: =IF(ROW()-2<=$C$11,$C$34+$C$37*COS(RADIANS((ROW()-3)*360/$C$11)),NA()) -> 70 | W7: =IF(ROW()-2<=$C$11,$C$34+$C$37*SIN(RADIANS((ROW()-3)*360/$C$11)),NA()) -> 300
A8: Bemessungswert des Moments im Schnitt (1. Ordnung) | B8: M_Ed | C8: 300 | D8: kNm | E8: 6.1 | Q8: =(ROW()-3)*10 -> 50 | R8: =$C$34+$C$34*COS(RADIANS(Q8)) -> 492.83628 | S8: =$C$34+$C$34*SIN(RADIANS(Q8)) -> 529.81333 | T8: =$C$34+($C$34-$C$10)*COS(RADIANS(Q8)) -> 460.6969 | U8: =$C$34+($C$34-$C$10)*SIN(RADIANS(Q8)) -> 491.51111 | V8: =IF(ROW()-2<=$C$11,$C$34+$C$37*COS(RADIANS((ROW()-3)*360/$C$11)),NA()) -> 137.36544 | W8: =IF(ROW()-2<=$C$11,$C$34+$C$37*SIN(RADIANS((ROW()-3)*360/$C$11)),NA()) -> 137.36544
A9: Pfahldurchmesser | B9: D = h | C9: 600 | D9: mm | E9: DIN EN 1536, 7.5 | Q9: =(ROW()-3)*10 -> 60 | R9: =$C$34+$C$34*COS(RADIANS(Q9)) -> 450 | S9: =$C$34+$C$34*SIN(RADIANS(Q9)) -> 559.80762 | T9: =$C$34+($C$34-$C$10)*COS(RADIANS(Q9)) -> 425 | U9: =$C$34+($C$34-$C$10)*SIN(RADIANS(Q9)) -> 516.50635 | V9: =IF(ROW()-2<=$C$11,$C$34+$C$37*COS(RADIANS((ROW()-3)*360/$C$11)),NA()) -> 300 | W9: =IF(ROW()-2<=$C$11,$C$34+$C$37*SIN(RADIANS((ROW()-3)*360/$C$11)),NA()) -> 70
A10: Nennmaß der Betondeckung | B10: c_nom | C10: 50 | D10: mm | E10: 4.4.1.1 / NA Tab. 4.4DE | Q10: =(ROW()-3)*10 -> 70 | R10: =$C$34+$C$34*COS(RADIANS(Q10)) -> 402.60604 | S10: =$C$34+$C$34*SIN(RADIANS(Q10)) -> 581.90779 | T10: =$C$34+($C$34-$C$10)*COS(RADIANS(Q10)) -> 385.50504 | U10: =$C$34+($C$34-$C$10)*SIN(RADIANS(Q10)) -> 534.92316 | V10: =IF(ROW()-2<=$C$11,$C$34+$C$37*COS(RADIANS((ROW()-3)*360/$C$11)),NA()) -> 462.63456 | W10: =IF(ROW()-2<=$C$11,$C$34+$C$37*SIN(RADIANS((ROW()-3)*360/$C$11)),NA()) -> 137.36544
A11: Anzahl der Längsbewehrungsstäbe | B11: n_l | C11: 8 | D11: - | E11: 9.8.5(3) | F11: ≥ 6 Stäbe | Q11: =(ROW()-3)*10 -> 80 | R11: =$C$34+$C$34*COS(RADIANS(Q11)) -> 352.09445 | S11: =$C$34+$C$34*SIN(RADIANS(Q11)) -> 595.44233 | T11: =$C$34+($C$34-$C$10)*COS(RADIANS(Q11)) -> 343.41204 | U11: =$C$34+($C$34-$C$10)*SIN(RADIANS(Q11)) -> 546.20194 | V11: =IF(ROW()-2<=$C$11,$C$34+$C$37*COS(RADIANS((ROW()-3)*360/$C$11)),NA()) -> #N/A | W11: =IF(ROW()-2<=$C$11,$C$34+$C$37*SIN(RADIANS((ROW()-3)*360/$C$11)),NA()) -> #N/A
A12: Durchmesser Längsstab | B12: Ø_l | C12: 20 | D12: mm | E12: 9.8.5(3) | F12: ≥ 16 mm | Q12: =(ROW()-3)*10 -> 90 | R12: =$C$34+$C$34*COS(RADIANS(Q12)) -> 300 | S12: =$C$34+$C$34*SIN(RADIANS(Q12)) -> 600 | T12: =$C$34+($C$34-$C$10)*COS(RADIANS(Q12)) -> 300 | U12: =$C$34+($C$34-$C$10)*SIN(RADIANS(Q12)) -> 550 | V12: =IF(ROW()-2<=$C$11,$C$34+$C$37*COS(RADIANS((ROW()-3)*360/$C$11)),NA()) -> #N/A | W12: =IF(ROW()-2<=$C$11,$C$34+$C$37*SIN(RADIANS((ROW()-3)*360/$C$11)),NA()) -> #N/A
A13: Durchmesser Wendel/Bügel | B13: Ø_w | C13: 10 | D13: mm | E13: DIN EN 1536, 7.5.2 | F13: ≥ 6 mm | Q13: =(ROW()-3)*10 -> 100 | R13: =$C$34+$C$34*COS(RADIANS(Q13)) -> 247.90555 | S13: =$C$34+$C$34*SIN(RADIANS(Q13)) -> 595.44233 | T13: =$C$34+($C$34-$C$10)*COS(RADIANS(Q13)) -> 256.58796 | U13: =$C$34+($C$34-$C$10)*SIN(RADIANS(Q13)) -> 546.20194 | V13: =IF(ROW()-2<=$C$11,$C$34+$C$37*COS(RADIANS((ROW()-3)*360/$C$11)),NA()) -> #N/A | W13: =IF(ROW()-2<=$C$11,$C$34+$C$37*SIN(RADIANS((ROW()-3)*360/$C$11)),NA()) -> #N/A
A14: Gewählte Ganghöhe der Wendel | B14: s_w | C14: 150 | D14: mm | E14: 9.2.2(6) / NA | Q14: =(ROW()-3)*10 -> 110 | R14: =$C$34+$C$34*COS(RADIANS(Q14)) -> 197.39396 | S14: =$C$34+$C$34*SIN(RADIANS(Q14)) -> 581.90779 | T14: =$C$34+($C$34-$C$10)*COS(RADIANS(Q14)) -> 214.49496 | U14: =$C$34+($C$34-$C$10)*SIN(RADIANS(Q14)) -> 534.92316 | V14: =IF(ROW()-2<=$C$11,$C$34+$C$37*COS(RADIANS((ROW()-3)*360/$C$11)),NA()) -> #N/A | W14: =IF(ROW()-2<=$C$11,$C$34+$C$37*SIN(RADIANS((ROW()-3)*360/$C$11)),NA()) -> #N/A
A15: Charakteristische Betondruckfestigkeit | B15: f_ck | C15: =_xlfn.XLOOKUP(F15,Aceros_DIN!$A$35:$A$43,Aceros_DIN!$B$35:$B$43) -> 25 | D15: N/mm² | E15: Tab. 3.1 | F15: C25/30 | Q15: =(ROW()-3)*10 -> 120 | R15: =$C$34+$C$34*COS(RADIANS(Q15)) -> 150 | S15: =$C$34+$C$34*SIN(RADIANS(Q15)) -> 559.80762 | T15: =$C$34+($C$34-$C$10)*COS(RADIANS(Q15)) -> 175 | U15: =$C$34+($C$34-$C$10)*SIN(RADIANS(Q15)) -> 516.50635 | V15: =IF(ROW()-2<=$C$11,$C$34+$C$37*COS(RADIANS((ROW()-3)*360/$C$11)),NA()) -> #N/A | W15: =IF(ROW()-2<=$C$11,$C$34+$C$37*SIN(RADIANS((ROW()-3)*360/$C$11)),NA()) -> #N/A
A16: Streckgrenze des Betonstahls | B16: f_yk | C16: =_xlfn.XLOOKUP(F16,Aceros_DIN!$A$47:$A$49,Aceros_DIN!$B$47:$B$49) -> 500 | D16: N/mm² | E16: 3.2.2 (B500) | F16: B500B | Q16: =(ROW()-3)*10 -> 130 | R16: =$C$34+$C$34*COS(RADIANS(Q16)) -> 107.16372 | S16: =$C$34+$C$34*SIN(RADIANS(Q16)) -> 529.81333 | T16: =$C$34+($C$34-$C$10)*COS(RADIANS(Q16)) -> 139.3031 | U16: =$C$34+($C$34-$C$10)*SIN(RADIANS(Q16)) -> 491.51111 | V16: =IF(ROW()-2<=$C$11,$C$34+$C$37*COS(RADIANS((ROW()-3)*360/$C$11)),NA()) -> #N/A | W16: =IF(ROW()-2<=$C$11,$C$34+$C$37*SIN(RADIANS((ROW()-3)*360/$C$11)),NA()) -> #N/A
A17: Teilsicherheitsbeiwert Beton | B17: γ_c | C17: 1.5 | D17: - | E17: Tab. 2.1DE (NA) | Q17: =(ROW()-3)*10 -> 140 | R17: =$C$34+$C$34*COS(RADIANS(Q17)) -> 70.186667 | S17: =$C$34+$C$34*SIN(RADIANS(Q17)) -> 492.83628 | T17: =$C$34+($C$34-$C$10)*COS(RADIANS(Q17)) -> 108.48889 | U17: =$C$34+($C$34-$C$10)*SIN(RADIANS(Q17)) -> 460.6969 | V17: =IF(ROW()-2<=$C$11,$C$34+$C$37*COS(RADIANS((ROW()-3)*360/$C$11)),NA()) -> #N/A | W17: =IF(ROW()-2<=$C$11,$C$34+$C$37*SIN(RADIANS((ROW()-3)*360/$C$11)),NA()) -> #N/A
A18: Teilsicherheitsbeiwert Betonstahl | B18: γ_s | C18: 1.15 | D18: - | E18: Tab. 2.1DE (NA) | Q18: =(ROW()-3)*10 -> 150 | R18: =$C$34+$C$34*COS(RADIANS(Q18)) -> 40.192379 | S18: =$C$34+$C$34*SIN(RADIANS(Q18)) -> 450 | T18: =$C$34+($C$34-$C$10)*COS(RADIANS(Q18)) -> 83.493649 | U18: =$C$34+($C$34-$C$10)*SIN(RADIANS(Q18)) -> 425 | V18: =IF(ROW()-2<=$C$11,$C$34+$C$37*COS(RADIANS((ROW()-3)*360/$C$11)),NA()) -> #N/A | W18: =IF(ROW()-2<=$C$11,$C$34+$C$37*SIN(RADIANS((ROW()-3)*360/$C$11)),NA()) -> #N/A
A19: Beiwert Belastungsdauer k_tc | B19: k_tc | C19: 1 | D19: - | E19: §5.1.6(1) | F19: k_tc = 1,0 (Last ≥ 3 Monate nach Betonage) oder 0,85 | Q19: =(ROW()-3)*10 -> 160 | R19: =$C$34+$C$34*COS(RADIANS(Q19)) -> 18.092214 | S19: =$C$34+$C$34*SIN(RADIANS(Q19)) -> 402.60604 | T19: =$C$34+($C$34-$C$10)*COS(RADIANS(Q19)) -> 65.076845 | U19: =$C$34+($C$34-$C$10)*SIN(RADIANS(Q19)) -> 385.50504 | V19: =IF(ROW()-2<=$C$11,$C$34+$C$37*COS(RADIANS((ROW()-3)*360/$C$11)),NA()) -> #N/A | W19: =IF(ROW()-2<=$C$11,$C$34+$C$37*SIN(RADIANS((ROW()-3)*360/$C$11)),NA()) -> #N/A
A20: Knicklänge (0 = Theorie II. Ordnung nicht ansetzen) | B20: l_0 | C20: 3000 | D20: mm | E20: 5.8.3.2 | Q20: =(ROW()-3)*10 -> 170 | R20: =$C$34+$C$34*COS(RADIANS(Q20)) -> 4.5576741 | S20: =$C$34+$C$34*SIN(RADIANS(Q20)) -> 352.09445 | T20: =$C$34+($C$34-$C$10)*COS(RADIANS(Q20)) -> 53.798062 | U20: =$C$34+($C$34-$C$10)*SIN(RADIANS(Q20)) -> 343.41204 | V20: =IF(ROW()-2<=$C$11,$C$34+$C$37*COS(RADIANS((ROW()-3)*360/$C$11)),NA()) -> #N/A | W20: =IF(ROW()-2<=$C$11,$C$34+$C$37*SIN(RADIANS((ROW()-3)*360/$C$11)),NA()) -> #N/A
A21: cot θ gewählt (0 = automatisch nach NA) | B21: cot θ | C21: 0 | D21: - | E21: NA 6.2.3(2), ec. (6.7aDE) | Q21: =(ROW()-3)*10 -> 180 | R21: =$C$34+$C$34*COS(RADIANS(Q21)) -> 0 | S21: =$C$34+$C$34*SIN(RADIANS(Q21)) -> 300 | T21: =$C$34+($C$34-$C$10)*COS(RADIANS(Q21)) -> 50 | U21: =$C$34+($C$34-$C$10)*SIN(RADIANS(Q21)) -> 300 | V21: =IF(ROW()-2<=$C$11,$C$34+$C$37*COS(RADIANS((ROW()-3)*360/$C$11)),NA()) -> #N/A | W21: =IF(ROW()-2<=$C$11,$C$34+$C$37*SIN(RADIANS((ROW()-3)*360/$C$11)),NA()) -> #N/A
Q22: =(ROW()-3)*10 -> 190 | R22: =$C$34+$C$34*COS(RADIANS(Q22)) -> 4.5576741 | S22: =$C$34+$C$34*SIN(RADIANS(Q22)) -> 247.90555 | T22: =$C$34+($C$34-$C$10)*COS(RADIANS(Q22)) -> 53.798062 | U22: =$C$34+($C$34-$C$10)*SIN(RADIANS(Q22)) -> 256.58796 | V22: =IF(ROW()-2<=$C$11,$C$34+$C$37*COS(RADIANS((ROW()-3)*360/$C$11)),NA()) -> #N/A | W22: =IF(ROW()-2<=$C$11,$C$34+$C$37*SIN(RADIANS((ROW()-3)*360/$C$11)),NA()) -> #N/A
A23: 2. BAUSTOFFE | Q23: =(ROW()-3)*10 -> 200 | R23: =$C$34+$C$34*COS(RADIANS(Q23)) -> 18.092214 | S23: =$C$34+$C$34*SIN(RADIANS(Q23)) -> 197.39396 | T23: =$C$34+($C$34-$C$10)*COS(RADIANS(Q23)) -> 65.076845 | U23: =$C$34+($C$34-$C$10)*SIN(RADIANS(Q23)) -> 214.49496 | V23: =IF(ROW()-2<=$C$11,$C$34+$C$37*COS(RADIANS((ROW()-3)*360/$C$11)),NA()) -> #N/A | W23: =IF(ROW()-2<=$C$11,$C$34+$C$37*SIN(RADIANS((ROW()-3)*360/$C$11)),NA()) -> #N/A
A24: Bemessungswert der Betondruckfestigkeit | B24: f_cd | C24: =MIN((40/C15)^(1/3),1)*C19*C15/C17 -> 16.666667 | D24: N/mm² | E24: §5.1.6(1), Gl. (5.3)/(5.4) | F24: f_cd = η_cc·k_tc·f_ck/γ_C ; η_cc=(40/f_ck)^⅓≤1,0 (f_ck,ref=40 MPa) | Q24: =(ROW()-3)*10 -> 210 | R24: =$C$34+$C$34*COS(RADIANS(Q24)) -> 40.192379 | S24: =$C$34+$C$34*SIN(RADIANS(Q24)) -> 150 | T24: =$C$34+($C$34-$C$10)*COS(RADIANS(Q24)) -> 83.493649 | U24: =$C$34+($C$34-$C$10)*SIN(RADIANS(Q24)) -> 175 | V24: =IF(ROW()-2<=$C$11,$C$34+$C$37*COS(RADIANS((ROW()-3)*360/$C$11)),NA()) -> #N/A | W24: =IF(ROW()-2<=$C$11,$C$34+$C$37*SIN(RADIANS((ROW()-3)*360/$C$11)),NA()) -> #N/A
A25: Mittlere Betonzugfestigkeit | B25: f_ctm | C25: =IF(C15<=50,0.3*C15^(2/3),2.12*LN(1+(C15+8)/10)) -> 2.5649639 | D25: N/mm² | E25: Tab. 5.1 | Q25: =(ROW()-3)*10 -> 220 | R25: =$C$34+$C$34*COS(RADIANS(Q25)) -> 70.186667 | S25: =$C$34+$C$34*SIN(RADIANS(Q25)) -> 107.16372 | T25: =$C$34+($C$34-$C$10)*COS(RADIANS(Q25)) -> 108.48889 | U25: =$C$34+($C$34-$C$10)*SIN(RADIANS(Q25)) -> 139.3031 | V25: =IF(ROW()-2<=$C$11,$C$34+$C$37*COS(RADIANS((ROW()-3)*360/$C$11)),NA()) -> #N/A | W25: =IF(ROW()-2<=$C$11,$C$34+$C$37*SIN(RADIANS((ROW()-3)*360/$C$11)),NA()) -> #N/A
A26: Bemessungswert der Stahlstreckgrenze | B26: f_yd | C26: =C16/C18 -> 434.78261 | D26: N/mm² | E26: §5.2.4, Bild 5.4 | Q26: =(ROW()-3)*10 -> 230 | R26: =$C$34+$C$34*COS(RADIANS(Q26)) -> 107.16372 | S26: =$C$34+$C$34*SIN(RADIANS(Q26)) -> 70.186667 | T26: =$C$34+($C$34-$C$10)*COS(RADIANS(Q26)) -> 139.3031 | U26: =$C$34+($C$34-$C$10)*SIN(RADIANS(Q26)) -> 108.48889 | V26: =IF(ROW()-2<=$C$11,$C$34+$C$37*COS(RADIANS((ROW()-3)*360/$C$11)),NA()) -> #N/A | W26: =IF(ROW()-2<=$C$11,$C$34+$C$37*SIN(RADIANS((ROW()-3)*360/$C$11)),NA()) -> #N/A
A27: Elastizitätsmodul Betonstahl | B27: E_s | C27: 200000 | D27: N/mm² | E27: §5.2.4 | Q27: =(ROW()-3)*10 -> 240 | R27: =$C$34+$C$34*COS(RADIANS(Q27)) -> 150 | S27: =$C$34+$C$34*SIN(RADIANS(Q27)) -> 40.192379 | T27: =$C$34+($C$34-$C$10)*COS(RADIANS(Q27)) -> 175 | U27: =$C$34+($C$34-$C$10)*SIN(RADIANS(Q27)) -> 83.493649
A28: Bemessungswert der Fließdehnung | B28: ε_yd | C28: =C26/C27 -> 0.002173913 | D28: - | E28: §5.2.4 | Q28: =(ROW()-3)*10 -> 250 | R28: =$C$34+$C$34*COS(RADIANS(Q28)) -> 197.39396 | S28: =$C$34+$C$34*SIN(RADIANS(Q28)) -> 18.092214 | T28: =$C$34+($C$34-$C$10)*COS(RADIANS(Q28)) -> 214.49496 | U28: =$C$34+($C$34-$C$10)*SIN(RADIANS(Q28)) -> 65.076845
A29: Grenzdehnung des Betons (Biegung) | B29: ε_cu2 | C29: 3.5 | D29: ‰ | E29: Tab. 5.1 / §8.1.2 | Q29: =(ROW()-3)*10 -> 260 | R29: =$C$34+$C$34*COS(RADIANS(Q29)) -> 247.90555 | S29: =$C$34+$C$34*SIN(RADIANS(Q29)) -> 4.5576741 | T29: =$C$34+($C$34-$C$10)*COS(RADIANS(Q29)) -> 256.58796 | U29: =$C$34+($C$34-$C$10)*SIN(RADIANS(Q29)) -> 53.798062
A30: Stauchung bei zentrischem Druck | B30: ε_c2 | C30: 2 | D30: ‰ | E30: Tab. 5.1 (Punkt C, §8.1.2) | Q30: =(ROW()-3)*10 -> 270 | R30: =$C$34+$C$34*COS(RADIANS(Q30)) -> 300 | S30: =$C$34+$C$34*SIN(RADIANS(Q30)) -> 0 | T30: =$C$34+($C$34-$C$10)*COS(RADIANS(Q30)) -> 300 | U30: =$C$34+($C$34-$C$10)*SIN(RADIANS(Q30)) -> 50
A31: Grenzdehnung des Betonstahls | B31: ε_ud | C31: 25 | D31: ‰ | E31: §5.2.4 (ε_ud = 25‰) | Q31: =(ROW()-3)*10 -> 280 | R31: =$C$34+$C$34*COS(RADIANS(Q31)) -> 352.09445 | S31: =$C$34+$C$34*SIN(RADIANS(Q31)) -> 4.5576741 | T31: =$C$34+($C$34-$C$10)*COS(RADIANS(Q31)) -> 343.41204 | U31: =$C$34+($C$34-$C$10)*SIN(RADIANS(Q31)) -> 53.798062
Q32: =(ROW()-3)*10 -> 290 | R32: =$C$34+$C$34*COS(RADIANS(Q32)) -> 402.60604 | S32: =$C$34+$C$34*SIN(RADIANS(Q32)) -> 18.092214 | T32: =$C$34+($C$34-$C$10)*COS(RADIANS(Q32)) -> 385.50504 | U32: =$C$34+($C$34-$C$10)*SIN(RADIANS(Q32)) -> 65.076845
A33: 3. QUERSCHNITTSGEOMETRIE | Q33: =(ROW()-3)*10 -> 300 | R33: =$C$34+$C$34*COS(RADIANS(Q33)) -> 450 | S33: =$C$34+$C$34*SIN(RADIANS(Q33)) -> 40.192379 | T33: =$C$34+($C$34-$C$10)*COS(RADIANS(Q33)) -> 425 | U33: =$C$34+($C$34-$C$10)*SIN(RADIANS(Q33)) -> 83.493649
A34: Außenradius | B34: r | C34: =C9/2 -> 300 | D34: mm | Q34: =(ROW()-3)*10 -> 310 | R34: =$C$34+$C$34*COS(RADIANS(Q34)) -> 492.83628 | S34: =$C$34+$C$34*SIN(RADIANS(Q34)) -> 70.186667 | T34: =$C$34+($C$34-$C$10)*COS(RADIANS(Q34)) -> 460.6969 | U34: =$C$34+($C$34-$C$10)*SIN(RADIANS(Q34)) -> 108.48889
A35: Betonquerschnittsfläche | B35: A_c | C35: =PI()*C9^2/4 -> 282743.34 | D35: mm² | Q35: =(ROW()-3)*10 -> 320 | R35: =$C$34+$C$34*COS(RADIANS(Q35)) -> 529.81333 | S35: =$C$34+$C$34*SIN(RADIANS(Q35)) -> 107.16372 | T35: =$C$34+($C$34-$C$10)*COS(RADIANS(Q35)) -> 491.51111 | U35: =$C$34+($C$34-$C$10)*SIN(RADIANS(Q35)) -> 139.3031
A36: Achsabstand Bewehrung vom Rand | B36: d_1 | C36: =C10+C13+C12/2 -> 70 | D36: mm | E36: 4.4.1 | Q36: =(ROW()-3)*10 -> 330 | R36: =$C$34+$C$34*COS(RADIANS(Q36)) -> 559.80762 | S36: =$C$34+$C$34*SIN(RADIANS(Q36)) -> 150 | T36: =$C$34+($C$34-$C$10)*COS(RADIANS(Q36)) -> 516.50635 | U36: =$C$34+($C$34-$C$10)*SIN(RADIANS(Q36)) -> 175
A37: Radius des Bewehrungskreises | B37: r_s | C37: =C34-C36 -> 230 | D37: mm | Q37: =(ROW()-3)*10 -> 340 | R37: =$C$34+$C$34*COS(RADIANS(Q37)) -> 581.90779 | S37: =$C$34+$C$34*SIN(RADIANS(Q37)) -> 197.39396 | T37: =$C$34+($C$34-$C$10)*COS(RADIANS(Q37)) -> 534.92316 | U37: =$C$34+($C$34-$C$10)*SIN(RADIANS(Q37)) -> 214.49496
A38: Rechnerische Nutzhöhe für Querkraft | B38: d | C38: =C34+2*C37/PI() -> 446.42255 | D38: mm | E38: 6.2.1 / DAfStb-Heft 600 | Q38: =(ROW()-3)*10 -> 350 | R38: =$C$34+$C$34*COS(RADIANS(Q38)) -> 595.44233 | S38: =$C$34+$C$34*SIN(RADIANS(Q38)) -> 247.90555 | T38: =$C$34+($C$34-$C$10)*COS(RADIANS(Q38)) -> 546.20194 | U38: =$C$34+($C$34-$C$10)*SIN(RADIANS(Q38)) -> 256.58796
A39: Innerer Hebelarm für Querkraft | B39: z | C39: =0.9*C38 -> 401.78029 | D39: mm | E39: 6.2.3(1) | Q39: =(ROW()-3)*10 -> 360 | R39: =$C$34+$C$34*COS(RADIANS(Q39)) -> 600 | S39: =$C$34+$C$34*SIN(RADIANS(Q39)) -> 300 | T39: =$C$34+($C$34-$C$10)*COS(RADIANS(Q39)) -> 550 | U39: =$C$34+($C$34-$C$10)*SIN(RADIANS(Q39)) -> 300
A40: Vorhandene Längsbewehrungsfläche | B40: A_s,prov | C40: =C11*PI()*C12^2/4 -> 2513.2741 | D40: mm²
...

Sheet Nomogramm
A1: DIMENSIONSLOSES μ–ν–ω-DIAGRAMM FÜR KREISQUERSCHNITTE MIT GLEICHMÄSSIG VERTEILTER BEWEHRUNG
A2: Querschnittsgleichgewicht nach DIN EN 1992-1-1, 6.1 und 3.1.7(3): rechteckiger Spannungsblock (λ = 0,8 ; η = 1,0 für f_ck ≤ 50 N/mm²); Dehnungsebene nach Bild 6.1 (Punkte B und C); bilineare Stahlkennlinie nach 3.2.7 Bild 3.8 mit horizontalem Ast (σ_s ≤ f_yd).
A4: Mit Blatt Pfahl_DIN verknüpfte Parameter | F4: Diskretisierung des Bewehrungsrings (24 Positionen gleicher Fläche)
A5: Durchmesser / Höhe | B5: h = D | C5: =Pfahl_DIN!C9 -> 600 | D5: mm | F5: i | G5: φ [°] | H5: d_i [mm] | I5: z_i [mm]
A6: Achsabstand der Bewehrung | B6: d_1 | C6: =Pfahl_DIN!C36 -> 70 | D6: mm | F6: 1 | G6: =(F6-1)*360/$C$17 -> 0 | H6: =$C$7-$C$8*COS(RADIANS(G6)) -> 70 | I6: =$C$7-H6 -> 230
A7: Außenradius | B7: r | C7: =C5/2 -> 300 | D7: mm | F7: =F6+1 -> 2 | G7: =(F7-1)*360/$C$17 -> 15 | H7: =$C$7-$C$8*COS(RADIANS(G7)) -> 77.83706 | I7: =$C$7-H7 -> 222.16294
A8: Radius des Bewehrungsrings | B8: r_s | C8: =C7-C6 -> 230 | D8: mm | F8: =F7+1 -> 3 | G8: =(F8-1)*360/$C$17 -> 30 | H8: =$C$7-$C$8*COS(RADIANS(G8)) -> 100.81416 | I8: =$C$7-H8 -> 199.18584
A9: Betonquerschnittsfläche | B9: A_c | C9: =Pfahl_DIN!C35 -> 282743.34 | D9: mm² | F9: =F8+1 -> 4 | G9: =(F9-1)*360/$C$17 -> 45 | H9: =$C$7-$C$8*COS(RADIANS(G9)) -> 137.36544 | I9: =$C$7-H9 -> 162.63456
A10: Bemessungswert der Betondruckfestigkeit | B10: f_cd | C10: =Pfahl_DIN!C24 -> 14.166667 | D10: N/mm² | F10: =F9+1 -> 5 | G10: =(F10-1)*360/$C$17 -> 60 | H10: =$C$7-$C$8*COS(RADIANS(G10)) -> 185 | I10: =$C$7-H10 -> 115
A11: Bemessungswert der Stahlstreckgrenze | B11: f_yd | C11: =Pfahl_DIN!C26 -> 434.78261 | D11: N/mm² | F11: =F10+1 -> 6 | G11: =(F11-1)*360/$C$17 -> 75 | H11: =$C$7-$C$8*COS(RADIANS(G11)) -> 240.47162 | I11: =$C$7-H11 -> 59.52838
A12: Grenzdehnung Beton (Punkt B) | B12: ε_cu2 | C12: =Pfahl_DIN!C29/1000 -> 0.0035 | D12: - | F12: =F11+1 -> 7 | G12: =(F12-1)*360/$C$17 -> 90 | H12: =$C$7-$C$8*COS(RADIANS(G12)) -> 300 | I12: =$C$7-H12 -> 0
A13: Stauchung bei zentrischem Druck (Punkt C) | B13: ε_c2 | C13: =Pfahl_DIN!C30/1000 -> 0.002 | D13: - | F13: =F12+1 -> 8 | G13: =(F13-1)*360/$C$17 -> 105 | H13: =$C$7-$C$8*COS(RADIANS(G13)) -> 359.52838 | I13: =$C$7-H13 -> -59.52838
A14: Bemessungswert der Fließdehnung | B14: ε_yd | C14: =Pfahl_DIN!C28 -> 0.002173913 | D14: - | F14: =F13+1 -> 9 | G14: =(F14-1)*360/$C$17 -> 120 | H14: =$C$7-$C$8*COS(RADIANS(G14)) -> 415 | I14: =$C$7-H14 -> -115
A15: Bezogene Normalkraft (Einwirkung) | B15: ν_Ed | C15: =Pfahl_DIN!C59 -> 0.24965481 | D15: - | F15: =F14+1 -> 10 | G15: =(F15-1)*360/$C$17 -> 135 | H15: =$C$7-$C$8*COS(RADIANS(G15)) -> 462.63456 | I15: =$C$7-H15 -> -162.63456
A16: Bezogenes Moment (Einwirkung) | B16: μ_Ed | C16: =Pfahl_DIN!C60 -> 0.12794809 | D16: - | F16: =F15+1 -> 11 | G16: =(F16-1)*360/$C$17 -> 150 | H16: =$C$7-$C$8*COS(RADIANS(G16)) -> 499.18584 | I16: =$C$7-H16 -> -199.18584
A17: Anzahl äquivalenter Stäbe im Ring | B17: n_div | C17: 24 | D17: - | F17: =F16+1 -> 12 | G17: =(F17-1)*360/$C$17 -> 165 | H17: =$C$7-$C$8*COS(RADIANS(G17)) -> 522.16294 | I17: =$C$7-H17 -> -222.16294
F18: =F17+1 -> 13 | G18: =(F18-1)*360/$C$17 -> 180 | H18: =$C$7-$C$8*COS(RADIANS(G18)) -> 530 | I18: =$C$7-H18 -> -230 | K18: Lineare Interpolation zwischen den beiden μ_Ed einschließenden Zeilen
A19: LÖSUNG — lineare Interpolation im Raster | F19: =F18+1 -> 14 | G19: =(F19-1)*360/$C$17 -> 195 | H19: =$C$7-$C$8*COS(RADIANS(G19)) -> 522.16294 | I19: =$C$7-H19 -> -222.16294 | K19: m1 = μ_Rd(i) | L19: {=INDEX($L$33:$L$212,$C$21)} -> 0.13396615
A20: Minimaler Fehler |μ_Rd − μ_Ed| | C20: =MIN(M33:M212) -> 0.0060180553 | F20: =F19+1 -> 15 | G20: =(F20-1)*360/$C$17 -> 210 | H20: =$C$7-$C$8*COS(RADIANS(G20)) -> 499.18584 | I20: =$C$7-H20 -> -199.18584 | K20: w1 = ω_erf(i) | L20: {=INDEX($K$33:$K$212,$C$21)} -> 0.21450162
A21: Nächstgelegene Rasterzeile | C21: =MATCH(C20,M33:M212,0) -> 37 | F21: =F20+1 -> 16 | G21: =(F21-1)*360/$C$17 -> 225 | H21: =$C$7-$C$8*COS(RADIANS(G21)) -> 462.63456 | I21: =$C$7-H21 -> -162.63456 | K21: Nachbarzeile j | L21: {=IF((L19-$C$16)*(IFERROR(INDEX($L$33:$L$212,$C$21+1),L19)-$C$16)<0,$C$21+1,MAX(1,$C$21-1))} -> 36
A22: Bezogene Druckzonenhöhe | B22: ξ = x/h | C22: {=INDEX(A33:A212,C21)} -> 0.41 | F22: =F21+1 -> 17 | G22: =(F22-1)*360/$C$17 -> 240 | H22: =$C$7-$C$8*COS(RADIANS(G22)) -> 415 | I22: =$C$7-H22 -> -115 | K22: m2 = μ_Rd(j) | L22: {=INDEX($L$33:$L$212,L21)} -> 0.11649908
A23: Druckzonenhöhe | B23: x | C23: =C22*C5 -> 246 | D23: mm | F23: =F22+1 -> 18 | G23: =(F23-1)*360/$C$17 -> 255 | H23: =$C$7-$C$8*COS(RADIANS(G23)) -> 359.52838 | I23: =$C$7-H23 -> -59.52838 | K23: w2 = ω_erf(j) | L23: {=INDEX($K$33:$K$212,L21)} -> 0.14192879
A24: Aufnehmbares Moment in dieser Zeile | B24: μ_Rd | C24: {=INDEX(L33:L212,C21)} -> 0.13396615 | F24: =F23+1 -> 19 | G24: =(F24-1)*360/$C$17 -> 270 | H24: =$C$7-$C$8*COS(RADIANS(G24)) -> 300 | I24: =$C$7-H24 -> 0 | K24: μ_Rd,min des gültigen Astes | L24: =MIN($L$33:$L$212) -> 0.089534792
A25: Maximales μ_Rd des Rasters (ω ≥ 0) | B25: μ_Rd,max | C25: =MAX(L33:L212) -> 1.3749486 | F25: =F24+1 -> 20 | G25: =(F25-1)*360/$C$17 -> 285 | H25: =$C$7-$C$8*COS(RADIANS(G25)) -> 240.47162 | I25: =$C$7-H25 -> 59.52838
